2020-02-04 22:00:43,117 (69593/MainThread) pgcli.main INFO - Default pager found in PAGER environment variable: "less"
2020-02-04 22:00:43,118 (69593/MainThread) pgcli.main WARNING - import keyring failed: ModuleNotFoundError("No module named 'keyring'").
2020-02-04 22:00:43,146 (69593/MainThread) pgcli.main ERROR - traceback: 'Traceback (most recent call last):\n  File "/usr/local/Cellar/pgcli/2.2.0_1/libexec/lib/python3.8/site-packages/pgcli/main.py", line 566, in connect\n    raise e\n  File "/usr/local/Cellar/pgcli/2.2.0_1/libexec/lib/python3.8/site-packages/pgcli/main.py", line 553, in connect\n    pgexecute = PGExecute(database, user, passwd, host, port, dsn, **kwargs)\n  File "/usr/local/Cellar/pgcli/2.2.0_1/libexec/lib/python3.8/site-packages/pgcli/pgexecute.py", line 215, in __init__\n    self.connect(database, user, password, host, port, dsn, **kwargs)\n  File "/usr/local/Cellar/pgcli/2.2.0_1/libexec/lib/python3.8/site-packages/pgcli/pgexecute.py", line 255, in connect\n    conn = psycopg2.connect(**conn_params)\n  File "/usr/local/Cellar/pgcli/2.2.0_1/libexec/lib/python3.8/site-packages/psycopg2/__init__.py", line 126, in connect\n    conn = _connect(dsn, connection_factory=connection_factory, **kwasync)\npsycopg2.OperationalError: could not connect to server: Connection refused\n\tIs the server running locally and accepting\n\tconnections on Unix domain socket "/tmp/.s.PGSQL.5432"?\n\n'
2020-02-04 22:29:20,619 (72903/MainThread) pgcli.main INFO - Default pager found in PAGER environment variable: "less"
2020-02-04 22:29:20,620 (72903/MainThread) pgcli.main WARNING - import keyring failed: ModuleNotFoundError("No module named 'keyring'").
2020-02-04 22:29:20,626 (72903/MainThread) pgcli.main ERROR - traceback: 'Traceback (most recent call last):\n  File "/usr/local/Cellar/pgcli/2.2.0_1/libexec/lib/python3.8/site-packages/pgcli/main.py", line 566, in connect\n    raise e\n  File "/usr/local/Cellar/pgcli/2.2.0_1/libexec/lib/python3.8/site-packages/pgcli/main.py", line 553, in connect\n    pgexecute = PGExecute(database, user, passwd, host, port, dsn, **kwargs)\n  File "/usr/local/Cellar/pgcli/2.2.0_1/libexec/lib/python3.8/site-packages/pgcli/pgexecute.py", line 215, in __init__\n    self.connect(database, user, password, host, port, dsn, **kwargs)\n  File "/usr/local/Cellar/pgcli/2.2.0_1/libexec/lib/python3.8/site-packages/pgcli/pgexecute.py", line 255, in connect\n    conn = psycopg2.connect(**conn_params)\n  File "/usr/local/Cellar/pgcli/2.2.0_1/libexec/lib/python3.8/site-packages/psycopg2/__init__.py", line 126, in connect\n    conn = _connect(dsn, connection_factory=connection_factory, **kwasync)\npsycopg2.OperationalError: could not connect to server: Connection refused\n\tIs the server running locally and accepting\n\tconnections on Unix domain socket "/tmp/.s.PGSQL.5432"?\n\n'
2020-02-05 00:23:53,789 (83368/MainThread) pgcli.main INFO - Default pager found in PAGER environment variable: "less"
2020-02-05 00:23:53,790 (83368/MainThread) pgcli.main WARNING - import keyring failed: ModuleNotFoundError("No module named 'keyring'").
2020-02-05 00:23:53,796 (83368/MainThread) pgcli.main ERROR - traceback: 'Traceback (most recent call last):\n  File "/usr/local/Cellar/pgcli/2.2.0_1/libexec/lib/python3.8/site-packages/pgcli/main.py", line 566, in connect\n    raise e\n  File "/usr/local/Cellar/pgcli/2.2.0_1/libexec/lib/python3.8/site-packages/pgcli/main.py", line 553, in connect\n    pgexecute = PGExecute(database, user, passwd, host, port, dsn, **kwargs)\n  File "/usr/local/Cellar/pgcli/2.2.0_1/libexec/lib/python3.8/site-packages/pgcli/pgexecute.py", line 215, in __init__\n    self.connect(database, user, password, host, port, dsn, **kwargs)\n  File "/usr/local/Cellar/pgcli/2.2.0_1/libexec/lib/python3.8/site-packages/pgcli/pgexecute.py", line 255, in connect\n    conn = psycopg2.connect(**conn_params)\n  File "/usr/local/Cellar/pgcli/2.2.0_1/libexec/lib/python3.8/site-packages/psycopg2/__init__.py", line 126, in connect\n    conn = _connect(dsn, connection_factory=connection_factory, **kwasync)\n  File "/usr/local/Cellar/pgcli/2.2.0_1/libexec/lib/python3.8/site-packages/pgcli/pgexecute.py", line 40, in _wait_select\n    state = conn.poll()\npsycopg2.OperationalError: could not connect to server: Connection refused\n\tIs the server running on host "localhost" (::1) and accepting\n\tTCP/IP connections on port 5432?\ncould not connect to server: Connection refused\n\tIs the server running on host "localhost" (127.0.0.1) and accepting\n\tTCP/IP connections on port 5432?\n\n'
2020-02-05 09:26:53,027 (87790/MainThread) pgcli.main INFO - Default pager found in PAGER environment variable: "less"
2020-02-05 09:26:53,028 (87790/MainThread) pgcli.main WARNING - import keyring failed: ModuleNotFoundError("No module named 'keyring'").
2020-02-05 09:45:08,185 (91782/MainThread) pgcli.main INFO - Default pager found in PAGER environment variable: "less"
2020-02-05 09:45:08,186 (91782/MainThread) pgcli.main WARNING - import keyring failed: ModuleNotFoundError("No module named 'keyring'").
2020-02-05 12:06:04,572 (96231/MainThread) pgcli.main INFO - Default pager found in PAGER environment variable: "less"
2020-02-05 12:06:04,573 (96231/MainThread) pgcli.main WARNING - import keyring failed: ModuleNotFoundError("No module named 'keyring'").
2020-02-05 13:03:55,440 (97040/MainThread) pgcli.main INFO - Default pager found in PAGER environment variable: "less"
2020-02-05 13:03:55,441 (97040/MainThread) pgcli.main WARNING - import keyring failed: ModuleNotFoundError("No module named 'keyring'").
2020-02-05 13:03:55,643 (97040/MainThread) pgcli.main ERROR - traceback: 'Traceback (most recent call last):\n  File "/usr/local/Cellar/pgcli/2.2.0_1/libexec/lib/python3.8/site-packages/pgcli/main.py", line 566, in connect\n    raise e\n  File "/usr/local/Cellar/pgcli/2.2.0_1/libexec/lib/python3.8/site-packages/pgcli/main.py", line 553, in connect\n    pgexecute = PGExecute(database, user, passwd, host, port, dsn, **kwargs)\n  File "/usr/local/Cellar/pgcli/2.2.0_1/libexec/lib/python3.8/site-packages/pgcli/pgexecute.py", line 215, in __init__\n    self.connect(database, user, password, host, port, dsn, **kwargs)\n  File "/usr/local/Cellar/pgcli/2.2.0_1/libexec/lib/python3.8/site-packages/pgcli/pgexecute.py", line 255, in connect\n    conn = psycopg2.connect(**conn_params)\n  File "/usr/local/Cellar/pgcli/2.2.0_1/libexec/lib/python3.8/site-packages/psycopg2/__init__.py", line 126, in connect\n    conn = _connect(dsn, connection_factory=connection_factory, **kwasync)\n  File "/usr/local/Cellar/pgcli/2.2.0_1/libexec/lib/python3.8/site-packages/pgcli/pgexecute.py", line 40, in _wait_select\n    state = conn.poll()\npsycopg2.OperationalError: server closed the connection unexpectedly\n\tThis probably means the server terminated abnormally\n\tbefore or while processing the request.\n\n'
2020-02-05 13:08:44,867 (97240/MainThread) pgcli.main INFO - Default pager found in PAGER environment variable: "less"
2020-02-05 13:08:44,868 (97240/MainThread) pgcli.main WARNING - import keyring failed: ModuleNotFoundError("No module named 'keyring'").
2020-02-05 13:44:43,087 (97978/MainThread) pgcli.main INFO - Default pager found in PAGER environment variable: "less"
2020-02-05 13:44:43,088 (97978/MainThread) pgcli.main WARNING - import keyring failed: ModuleNotFoundError("No module named 'keyring'").
2020-02-05 13:57:50,205 (99596/MainThread) pgcli.main INFO - Default pager found in PAGER environment variable: "less"
2020-02-05 13:57:50,206 (99596/MainThread) pgcli.main WARNING - import keyring failed: ModuleNotFoundError("No module named 'keyring'").
2020-02-05 13:57:50,849 (99596/MainThread) pgcli.main ERROR - traceback: 'Traceback (most recent call last):\n  File "/usr/local/Cellar/pgcli/2.2.0_1/libexec/lib/python3.8/site-packages/pgcli/main.py", line 566, in connect\n    raise e\n  File "/usr/local/Cellar/pgcli/2.2.0_1/libexec/lib/python3.8/site-packages/pgcli/main.py", line 553, in connect\n    pgexecute = PGExecute(database, user, passwd, host, port, dsn, **kwargs)\n  File "/usr/local/Cellar/pgcli/2.2.0_1/libexec/lib/python3.8/site-packages/pgcli/pgexecute.py", line 215, in __init__\n    self.connect(database, user, password, host, port, dsn, **kwargs)\n  File "/usr/local/Cellar/pgcli/2.2.0_1/libexec/lib/python3.8/site-packages/pgcli/pgexecute.py", line 255, in connect\n    conn = psycopg2.connect(**conn_params)\n  File "/usr/local/Cellar/pgcli/2.2.0_1/libexec/lib/python3.8/site-packages/psycopg2/__init__.py", line 126, in connect\n    conn = _connect(dsn, connection_factory=connection_factory, **kwasync)\n  File "/usr/local/Cellar/pgcli/2.2.0_1/libexec/lib/python3.8/site-packages/pgcli/pgexecute.py", line 40, in _wait_select\n    state = conn.poll()\npsycopg2.OperationalError: server closed the connection unexpectedly\n\tThis probably means the server terminated abnormally\n\tbefore or while processing the request.\n\n'
2020-02-05 13:59:20,806 (99967/MainThread) pgcli.main INFO - Default pager found in PAGER environment variable: "less"
2020-02-05 13:59:20,807 (99967/MainThread) pgcli.main WARNING - import keyring failed: ModuleNotFoundError("No module named 'keyring'").
2020-02-05 14:03:18,074 (612/MainThread) pgcli.main INFO - Default pager found in PAGER environment variable: "less"
2020-02-05 14:03:18,075 (612/MainThread) pgcli.main WARNING - import keyring failed: ModuleNotFoundError("No module named 'keyring'").
2020-02-05 14:03:18,081 (612/MainThread) pgcli.main ERROR - traceback: 'Traceback (most recent call last):\n  File "/usr/local/Cellar/pgcli/2.2.0_1/libexec/lib/python3.8/site-packages/pgcli/main.py", line 566, in connect\n    raise e\n  File "/usr/local/Cellar/pgcli/2.2.0_1/libexec/lib/python3.8/site-packages/pgcli/main.py", line 553, in connect\n    pgexecute = PGExecute(database, user, passwd, host, port, dsn, **kwargs)\n  File "/usr/local/Cellar/pgcli/2.2.0_1/libexec/lib/python3.8/site-packages/pgcli/pgexecute.py", line 215, in __init__\n    self.connect(database, user, password, host, port, dsn, **kwargs)\n  File "/usr/local/Cellar/pgcli/2.2.0_1/libexec/lib/python3.8/site-packages/pgcli/pgexecute.py", line 255, in connect\n    conn = psycopg2.connect(**conn_params)\n  File "/usr/local/Cellar/pgcli/2.2.0_1/libexec/lib/python3.8/site-packages/psycopg2/__init__.py", line 126, in connect\n    conn = _connect(dsn, connection_factory=connection_factory, **kwasync)\n  File "/usr/local/Cellar/pgcli/2.2.0_1/libexec/lib/python3.8/site-packages/pgcli/pgexecute.py", line 40, in _wait_select\n    state = conn.poll()\npsycopg2.OperationalError: could not connect to server: Connection refused\n\tIs the server running on host "localhost" (::1) and accepting\n\tTCP/IP connections on port 5432?\ncould not connect to server: Connection refused\n\tIs the server running on host "localhost" (127.0.0.1) and accepting\n\tTCP/IP connections on port 5432?\n\n'
2020-02-05 14:04:04,964 (845/MainThread) pgcli.main INFO - Default pager found in PAGER environment variable: "less"
2020-02-05 14:04:04,965 (845/MainThread) pgcli.main WARNING - import keyring failed: ModuleNotFoundError("No module named 'keyring'").
2020-02-05 14:04:08,283 (845/MainThread) pgcli.main ERROR - traceback: 'Traceback (most recent call last):\n  File "/usr/local/Cellar/pgcli/2.2.0_1/libexec/lib/python3.8/site-packages/pgcli/main.py", line 553, in connect\n    pgexecute = PGExecute(database, user, passwd, host, port, dsn, **kwargs)\n  File "/usr/local/Cellar/pgcli/2.2.0_1/libexec/lib/python3.8/site-packages/pgcli/pgexecute.py", line 215, in __init__\n    self.connect(database, user, password, host, port, dsn, **kwargs)\n  File "/usr/local/Cellar/pgcli/2.2.0_1/libexec/lib/python3.8/site-packages/pgcli/pgexecute.py", line 255, in connect\n    conn = psycopg2.connect(**conn_params)\n  File "/usr/local/Cellar/pgcli/2.2.0_1/libexec/lib/python3.8/site-packages/psycopg2/__init__.py", line 126, in connect\n    conn = _connect(dsn, connection_factory=connection_factory, **kwasync)\n  File "/usr/local/Cellar/pgcli/2.2.0_1/libexec/lib/python3.8/site-packages/pgcli/pgexecute.py", line 40, in _wait_select\n    state = conn.poll()\npsycopg2.OperationalError: fe_sendauth: no password supplied\n\n\nDuring handling of the above exception, another exception occurred:\n\nTraceback (most recent call last):\n  File "/usr/local/Cellar/pgcli/2.2.0_1/libexec/lib/python3.8/site-packages/pgcli/main.py", line 562, in connect\n    pgexecute = PGExecute(\n  File "/usr/local/Cellar/pgcli/2.2.0_1/libexec/lib/python3.8/site-packages/pgcli/pgexecute.py", line 215, in __init__\n    self.connect(database, user, password, host, port, dsn, **kwargs)\n  File "/usr/local/Cellar/pgcli/2.2.0_1/libexec/lib/python3.8/site-packages/pgcli/pgexecute.py", line 255, in connect\n    conn = psycopg2.connect(**conn_params)\n  File "/usr/local/Cellar/pgcli/2.2.0_1/libexec/lib/python3.8/site-packages/psycopg2/__init__.py", line 126, in connect\n    conn = _connect(dsn, connection_factory=connection_factory, **kwasync)\n  File "/usr/local/Cellar/pgcli/2.2.0_1/libexec/lib/python3.8/site-packages/pgcli/pgexecute.py", line 40, in _wait_select\n    state = conn.poll()\npsycopg2.OperationalError: FATAL:  database "ebroot" does not exist\n\n'
2020-02-05 14:05:39,202 (1137/MainThread) pgcli.main INFO - Default pager found in PAGER environment variable: "less"
2020-02-05 14:05:39,204 (1137/MainThread) pgcli.main WARNING - import keyring failed: ModuleNotFoundError("No module named 'keyring'").
2020-02-05 14:05:42,498 (1137/MainThread) pgcli.main ERROR - traceback: 'Traceback (most recent call last):\n  File "/usr/local/Cellar/pgcli/2.2.0_1/libexec/lib/python3.8/site-packages/pgcli/main.py", line 553, in connect\n    pgexecute = PGExecute(database, user, passwd, host, port, dsn, **kwargs)\n  File "/usr/local/Cellar/pgcli/2.2.0_1/libexec/lib/python3.8/site-packages/pgcli/pgexecute.py", line 215, in __init__\n    self.connect(database, user, password, host, port, dsn, **kwargs)\n  File "/usr/local/Cellar/pgcli/2.2.0_1/libexec/lib/python3.8/site-packages/pgcli/pgexecute.py", line 255, in connect\n    conn = psycopg2.connect(**conn_params)\n  File "/usr/local/Cellar/pgcli/2.2.0_1/libexec/lib/python3.8/site-packages/psycopg2/__init__.py", line 126, in connect\n    conn = _connect(dsn, connection_factory=connection_factory, **kwasync)\n  File "/usr/local/Cellar/pgcli/2.2.0_1/libexec/lib/python3.8/site-packages/pgcli/pgexecute.py", line 40, in _wait_select\n    state = conn.poll()\npsycopg2.OperationalError: fe_sendauth: no password supplied\n\n\nDuring handling of the above exception, another exception occurred:\n\nTraceback (most recent call last):\n  File "/usr/local/Cellar/pgcli/2.2.0_1/libexec/lib/python3.8/site-packages/pgcli/main.py", line 562, in connect\n    pgexecute = PGExecute(\n  File "/usr/local/Cellar/pgcli/2.2.0_1/libexec/lib/python3.8/site-packages/pgcli/pgexecute.py", line 215, in __init__\n    self.connect(database, user, password, host, port, dsn, **kwargs)\n  File "/usr/local/Cellar/pgcli/2.2.0_1/libexec/lib/python3.8/site-packages/pgcli/pgexecute.py", line 255, in connect\n    conn = psycopg2.connect(**conn_params)\n  File "/usr/local/Cellar/pgcli/2.2.0_1/libexec/lib/python3.8/site-packages/psycopg2/__init__.py", line 126, in connect\n    conn = _connect(dsn, connection_factory=connection_factory, **kwasync)\n  File "/usr/local/Cellar/pgcli/2.2.0_1/libexec/lib/python3.8/site-packages/pgcli/pgexecute.py", line 40, in _wait_select\n    state = conn.poll()\npsycopg2.OperationalError: FATAL:  database "ebroot" does not exist\n\n'
2020-02-05 14:05:55,894 (1151/MainThread) pgcli.main INFO - Default pager found in PAGER environment variable: "less"
2020-02-05 14:05:55,896 (1151/MainThread) pgcli.main WARNING - import keyring failed: ModuleNotFoundError("No module named 'keyring'").
2020-02-05 14:05:58,415 (1151/MainThread) pgcli.main ERROR - traceback: 'Traceback (most recent call last):\n  File "/usr/local/Cellar/pgcli/2.2.0_1/libexec/lib/python3.8/site-packages/pgcli/main.py", line 553, in connect\n    pgexecute = PGExecute(database, user, passwd, host, port, dsn, **kwargs)\n  File "/usr/local/Cellar/pgcli/2.2.0_1/libexec/lib/python3.8/site-packages/pgcli/pgexecute.py", line 215, in __init__\n    self.connect(database, user, password, host, port, dsn, **kwargs)\n  File "/usr/local/Cellar/pgcli/2.2.0_1/libexec/lib/python3.8/site-packages/pgcli/pgexecute.py", line 255, in connect\n    conn = psycopg2.connect(**conn_params)\n  File "/usr/local/Cellar/pgcli/2.2.0_1/libexec/lib/python3.8/site-packages/psycopg2/__init__.py", line 126, in connect\n    conn = _connect(dsn, connection_factory=connection_factory, **kwasync)\n  File "/usr/local/Cellar/pgcli/2.2.0_1/libexec/lib/python3.8/site-packages/pgcli/pgexecute.py", line 40, in _wait_select\n    state = conn.poll()\npsycopg2.OperationalError: fe_sendauth: no password supplied\n\n\nDuring handling of the above exception, another exception occurred:\n\nTraceback (most recent call last):\n  File "/usr/local/Cellar/pgcli/2.2.0_1/libexec/lib/python3.8/site-packages/pgcli/main.py", line 562, in connect\n    pgexecute = PGExecute(\n  File "/usr/local/Cellar/pgcli/2.2.0_1/libexec/lib/python3.8/site-packages/pgcli/pgexecute.py", line 215, in __init__\n    self.connect(database, user, password, host, port, dsn, **kwargs)\n  File "/usr/local/Cellar/pgcli/2.2.0_1/libexec/lib/python3.8/site-packages/pgcli/pgexecute.py", line 255, in connect\n    conn = psycopg2.connect(**conn_params)\n  File "/usr/local/Cellar/pgcli/2.2.0_1/libexec/lib/python3.8/site-packages/psycopg2/__init__.py", line 126, in connect\n    conn = _connect(dsn, connection_factory=connection_factory, **kwasync)\n  File "/usr/local/Cellar/pgcli/2.2.0_1/libexec/lib/python3.8/site-packages/pgcli/pgexecute.py", line 40, in _wait_select\n    state = conn.poll()\npsycopg2.OperationalError: FATAL:  database "notify_me_db" does not exist\n\n'
2020-02-05 14:08:14,244 (1454/MainThread) pgcli.main INFO - Default pager found in PAGER environment variable: "less"
2020-02-05 14:08:14,245 (1454/MainThread) pgcli.main WARNING - import keyring failed: ModuleNotFoundError("No module named 'keyring'").
2020-02-05 14:08:27,187 (1454/MainThread) pgcli.pgexecute ERROR - sql: 'select * from user_profile_user limit 1', error: UndefinedTable('relation "user_profile_user" does not exist\nLINE 1: select * from user_profile_user limit 1\n                      ^\n')
2020-02-05 14:08:27,188 (1454/MainThread) pgcli.pgexecute ERROR - traceback: 'Traceback (most recent call last):\n  File "/usr/local/Cellar/pgcli/2.2.0_1/libexec/lib/python3.8/site-packages/pgcli/pgexecute.py", line 413, in run\n    yield self.execute_normal_sql(sql) + (sql, True, False)\n  File "/usr/local/Cellar/pgcli/2.2.0_1/libexec/lib/python3.8/site-packages/pgcli/pgexecute.py", line 448, in execute_normal_sql\n    cur.execute(split_sql)\npsycopg2.errors.UndefinedTable: relation "user_profile_user" does not exist\nLINE 1: select * from user_profile_user limit 1\n                      ^\n\n'
2020-02-05 14:10:09,566 (1780/MainThread) pgcli.main INFO - Default pager found in PAGER environment variable: "less"
2020-02-05 14:10:09,567 (1780/MainThread) pgcli.main WARNING - import keyring failed: ModuleNotFoundError("No module named 'keyring'").
2020-02-05 14:10:15,075 (1780/MainThread) pgcli.pgexecute ERROR - sql: 'select * from user_profile_user limit 1', error: UndefinedTable('relation "user_profile_user" does not exist\nLINE 1: select * from user_profile_user limit 1\n                      ^\n')
2020-02-05 14:10:15,082 (1780/MainThread) pgcli.pgexecute ERROR - traceback: 'Traceback (most recent call last):\n  File "/usr/local/Cellar/pgcli/2.2.0_1/libexec/lib/python3.8/site-packages/pgcli/pgexecute.py", line 413, in run\n    yield self.execute_normal_sql(sql) + (sql, True, False)\n  File "/usr/local/Cellar/pgcli/2.2.0_1/libexec/lib/python3.8/site-packages/pgcli/pgexecute.py", line 448, in execute_normal_sql\n    cur.execute(split_sql)\npsycopg2.errors.UndefinedTable: relation "user_profile_user" does not exist\nLINE 1: select * from user_profile_user limit 1\n                      ^\n\n'
2020-02-05 14:47:14,581 (5721/MainThread) pgcli.main INFO - Default pager found in PAGER environment variable: "less"
2020-02-05 14:47:14,582 (5721/MainThread) pgcli.main WARNING - import keyring failed: ModuleNotFoundError("No module named 'keyring'").
2020-02-05 14:47:21,447 (5721/MainThread) pgcli.pgexecute ERROR - sql: 'select * from user_profile_user limit 1', error: UndefinedTable('relation "user_profile_user" does not exist\nLINE 1: select * from user_profile_user limit 1\n                      ^\n')
2020-02-05 14:47:21,449 (5721/MainThread) pgcli.pgexecute ERROR - traceback: 'Traceback (most recent call last):\n  File "/usr/local/Cellar/pgcli/2.2.0_1/libexec/lib/python3.8/site-packages/pgcli/pgexecute.py", line 413, in run\n    yield self.execute_normal_sql(sql) + (sql, True, False)\n  File "/usr/local/Cellar/pgcli/2.2.0_1/libexec/lib/python3.8/site-packages/pgcli/pgexecute.py", line 448, in execute_normal_sql\n    cur.execute(split_sql)\npsycopg2.errors.UndefinedTable: relation "user_profile_user" does not exist\nLINE 1: select * from user_profile_user limit 1\n                      ^\n\n'
2020-02-05 14:57:57,411 (7297/MainThread) pgcli.main INFO - Default pager found in PAGER environment variable: "less"
2020-02-05 14:57:57,412 (7297/MainThread) pgcli.main WARNING - import keyring failed: ModuleNotFoundError("No module named 'keyring'").
2020-02-05 15:01:32,796 (7297/MainThread) pgcli.pgexecute ERROR - sql: 'select * from zip_codes \\', error: SyntaxError('syntax error at or near "\\"\nLINE 1: select * from zip_codes \\\n                                ^\n')
2020-02-05 15:01:32,802 (7297/MainThread) pgcli.pgexecute ERROR - traceback: 'Traceback (most recent call last):\n  File "/usr/local/Cellar/pgcli/2.2.0_1/libexec/lib/python3.8/site-packages/pgcli/pgexecute.py", line 413, in run\n    yield self.execute_normal_sql(sql) + (sql, True, False)\n  File "/usr/local/Cellar/pgcli/2.2.0_1/libexec/lib/python3.8/site-packages/pgcli/pgexecute.py", line 448, in execute_normal_sql\n    cur.execute(split_sql)\npsycopg2.errors.SyntaxError: syntax error at or near "\\"\nLINE 1: select * from zip_codes \\\n                                ^\n\n'
2020-02-05 15:04:51,069 (7297/MainThread) pgcli.pgexecute ERROR - sql: "select * from user_profile_user where name='joe'", error: UndefinedColumn('column "name" does not exist\nLINE 1: select * from user_profile_user where name=\'joe\'\n                                              ^\n')
2020-02-05 15:04:51,072 (7297/MainThread) pgcli.pgexecute ERROR - traceback: 'Traceback (most recent call last):\n  File "/usr/local/Cellar/pgcli/2.2.0_1/libexec/lib/python3.8/site-packages/pgcli/pgexecute.py", line 413, in run\n    yield self.execute_normal_sql(sql) + (sql, True, False)\n  File "/usr/local/Cellar/pgcli/2.2.0_1/libexec/lib/python3.8/site-packages/pgcli/pgexecute.py", line 448, in execute_normal_sql\n    cur.execute(split_sql)\npsycopg2.errors.UndefinedColumn: column "name" does not exist\nLINE 1: select * from user_profile_user where name=\'joe\'\n                                              ^\n\n'
2020-02-05 15:04:56,335 (7297/MainThread) pgcli.pgexecute ERROR - sql: "select * from user_profile_user where name = 'joe'", error: UndefinedColumn('column "name" does not exist\nLINE 1: select * from user_profile_user where name = \'joe\'\n                                              ^\n')
2020-02-05 15:04:56,337 (7297/MainThread) pgcli.pgexecute ERROR - traceback: 'Traceback (most recent call last):\n  File "/usr/local/Cellar/pgcli/2.2.0_1/libexec/lib/python3.8/site-packages/pgcli/pgexecute.py", line 413, in run\n    yield self.execute_normal_sql(sql) + (sql, True, False)\n  File "/usr/local/Cellar/pgcli/2.2.0_1/libexec/lib/python3.8/site-packages/pgcli/pgexecute.py", line 448, in execute_normal_sql\n    cur.execute(split_sql)\npsycopg2.errors.UndefinedColumn: column "name" does not exist\nLINE 1: select * from user_profile_user where name = \'joe\'\n                                              ^\n\n'
2020-02-05 15:42:57,859 (20131/MainThread) pgcli.main INFO - Default pager found in PAGER environment variable: "less"
2020-02-05 15:42:57,860 (20131/MainThread) pgcli.main WARNING - import keyring failed: ModuleNotFoundError("No module named 'keyring'").
2020-02-06 11:28:40,789 (26584/MainThread) pgcli.main INFO - Default pager found in PAGER environment variable: "less"
2020-02-06 11:28:40,790 (26584/MainThread) pgcli.main WARNING - import keyring failed: ModuleNotFoundError("No module named 'keyring'").
2020-02-09 22:37:36,006 (29341/MainThread) pgcli.main INFO - Default pager found in PAGER environment variable: "less"
2020-02-09 22:37:36,007 (29341/MainThread) pgcli.main WARNING - import keyring failed: ModuleNotFoundError("No module named 'keyring'").
2020-02-09 22:37:36,036 (29341/MainThread) pgcli.main ERROR - traceback: 'Traceback (most recent call last):\n  File "/usr/local/Cellar/pgcli/2.2.0_1/libexec/lib/python3.8/site-packages/pgcli/main.py", line 566, in connect\n    raise e\n  File "/usr/local/Cellar/pgcli/2.2.0_1/libexec/lib/python3.8/site-packages/pgcli/main.py", line 553, in connect\n    pgexecute = PGExecute(database, user, passwd, host, port, dsn, **kwargs)\n  File "/usr/local/Cellar/pgcli/2.2.0_1/libexec/lib/python3.8/site-packages/pgcli/pgexecute.py", line 215, in __init__\n    self.connect(database, user, password, host, port, dsn, **kwargs)\n  File "/usr/local/Cellar/pgcli/2.2.0_1/libexec/lib/python3.8/site-packages/pgcli/pgexecute.py", line 255, in connect\n    conn = psycopg2.connect(**conn_params)\n  File "/usr/local/Cellar/pgcli/2.2.0_1/libexec/lib/python3.8/site-packages/psycopg2/__init__.py", line 126, in connect\n    conn = _connect(dsn, connection_factory=connection_factory, **kwasync)\npsycopg2.OperationalError: could not connect to server: No such file or directory\n\tIs the server running locally and accepting\n\tconnections on Unix domain socket "/tmp/.s.PGSQL.5432"?\n\n'
2020-02-09 22:37:41,465 (29349/MainThread) pgcli.main INFO - Default pager found in PAGER environment variable: "less"
2020-02-09 22:37:41,466 (29349/MainThread) pgcli.main WARNING - import keyring failed: ModuleNotFoundError("No module named 'keyring'").
2020-02-09 22:38:42,886 (29349/MainThread) pgcli.pgexecute ERROR - sql: 'close', error: SyntaxError('syntax error at end of input\nLINE 1: close\n             ^\n')
2020-02-09 22:38:42,888 (29349/MainThread) pgcli.pgexecute ERROR - traceback: 'Traceback (most recent call last):\n  File "/usr/local/Cellar/pgcli/2.2.0_1/libexec/lib/python3.8/site-packages/pgcli/pgexecute.py", line 413, in run\n    yield self.execute_normal_sql(sql) + (sql, True, False)\n  File "/usr/local/Cellar/pgcli/2.2.0_1/libexec/lib/python3.8/site-packages/pgcli/pgexecute.py", line 448, in execute_normal_sql\n    cur.execute(split_sql)\npsycopg2.errors.SyntaxError: syntax error at end of input\nLINE 1: close\n             ^\n\n'
2020-02-10 12:18:58,337 (44007/MainThread) pgcli.main INFO - Default pager found in PAGER environment variable: "less"
2020-02-10 12:18:58,338 (44007/MainThread) pgcli.main WARNING - import keyring failed: ModuleNotFoundError("No module named 'keyring'").
2020-03-16 11:00:13,273 (87123/MainThread) pgcli.main INFO - Default pager found in PAGER environment variable: "less"
2020-03-16 11:00:13,274 (87123/MainThread) pgcli.main WARNING - import keyring failed: ModuleNotFoundError("No module named 'keyring'").
2020-03-16 11:00:13,304 (87123/MainThread) pgcli.main ERROR - traceback: 'Traceback (most recent call last):\n  File "/usr/local/Cellar/pgcli/2.2.0_1/libexec/lib/python3.8/site-packages/pgcli/main.py", line 566, in connect\n    raise e\n  File "/usr/local/Cellar/pgcli/2.2.0_1/libexec/lib/python3.8/site-packages/pgcli/main.py", line 553, in connect\n    pgexecute = PGExecute(database, user, passwd, host, port, dsn, **kwargs)\n  File "/usr/local/Cellar/pgcli/2.2.0_1/libexec/lib/python3.8/site-packages/pgcli/pgexecute.py", line 215, in __init__\n    self.connect(database, user, password, host, port, dsn, **kwargs)\n  File "/usr/local/Cellar/pgcli/2.2.0_1/libexec/lib/python3.8/site-packages/pgcli/pgexecute.py", line 255, in connect\n    conn = psycopg2.connect(**conn_params)\n  File "/usr/local/Cellar/pgcli/2.2.0_1/libexec/lib/python3.8/site-packages/psycopg2/__init__.py", line 126, in connect\n    conn = _connect(dsn, connection_factory=connection_factory, **kwasync)\npsycopg2.OperationalError: could not connect to server: No such file or directory\n\tIs the server running locally and accepting\n\tconnections on Unix domain socket "/tmp/.s.PGSQL.5432"?\n\n'
2020-04-30 09:07:40,569 (45980/MainThread) pgcli.main INFO - Default pager found in PAGER environment variable: "less"
2020-04-30 09:07:40,570 (45980/MainThread) pgcli.main WARNING - import keyring failed: ModuleNotFoundError("No module named 'keyring'").
2020-04-30 09:07:40,598 (45980/MainThread) pgcli.main ERROR - traceback: 'Traceback (most recent call last):\n  File "/usr/local/Cellar/pgcli/2.2.0_1/libexec/lib/python3.8/site-packages/pgcli/main.py", line 566, in connect\n    raise e\n  File "/usr/local/Cellar/pgcli/2.2.0_1/libexec/lib/python3.8/site-packages/pgcli/main.py", line 553, in connect\n    pgexecute = PGExecute(database, user, passwd, host, port, dsn, **kwargs)\n  File "/usr/local/Cellar/pgcli/2.2.0_1/libexec/lib/python3.8/site-packages/pgcli/pgexecute.py", line 215, in __init__\n    self.connect(database, user, password, host, port, dsn, **kwargs)\n  File "/usr/local/Cellar/pgcli/2.2.0_1/libexec/lib/python3.8/site-packages/pgcli/pgexecute.py", line 255, in connect\n    conn = psycopg2.connect(**conn_params)\n  File "/usr/local/Cellar/pgcli/2.2.0_1/libexec/lib/python3.8/site-packages/psycopg2/__init__.py", line 126, in connect\n    conn = _connect(dsn, connection_factory=connection_factory, **kwasync)\npsycopg2.OperationalError: could not connect to server: No such file or directory\n\tIs the server running locally and accepting\n\tconnections on Unix domain socket "/tmp/.s.PGSQL.5432"?\n\n'
2020-08-05 11:34:24,565 (57549/MainThread) pgcli.main INFO - Default pager found in PAGER environment variable: "less"
2020-08-05 11:34:24,566 (57549/MainThread) pgcli.main WARNING - import keyring failed: ModuleNotFoundError("No module named 'keyring'").
2020-08-05 11:34:24,679 (57549/MainThread) pgcli.main ERROR - traceback: 'Traceback (most recent call last):\n  File "/usr/local/Cellar/pgcli/2.2.0_1/libexec/lib/python3.8/site-packages/pgcli/main.py", line 566, in connect\n    raise e\n  File "/usr/local/Cellar/pgcli/2.2.0_1/libexec/lib/python3.8/site-packages/pgcli/main.py", line 553, in connect\n    pgexecute = PGExecute(database, user, passwd, host, port, dsn, **kwargs)\n  File "/usr/local/Cellar/pgcli/2.2.0_1/libexec/lib/python3.8/site-packages/pgcli/pgexecute.py", line 215, in __init__\n    self.connect(database, user, password, host, port, dsn, **kwargs)\n  File "/usr/local/Cellar/pgcli/2.2.0_1/libexec/lib/python3.8/site-packages/pgcli/pgexecute.py", line 255, in connect\n    conn = psycopg2.connect(**conn_params)\n  File "/usr/local/Cellar/pgcli/2.2.0_1/libexec/lib/python3.8/site-packages/psycopg2/__init__.py", line 126, in connect\n    conn = _connect(dsn, connection_factory=connection_factory, **kwasync)\npsycopg2.OperationalError: could not translate host name "staging-notify-me.candtmezd0mj.us-west-1.rds.amazonaws.com" to address: nodename nor servname provided, or not known\n\n'
2020-08-05 11:36:37,072 (57597/MainThread) pgcli.main INFO - Default pager found in PAGER environment variable: "less"
2020-08-05 11:36:37,073 (57597/MainThread) pgcli.main WARNING - import keyring failed: ModuleNotFoundError("No module named 'keyring'").
2020-08-05 11:40:13,892 (57597/MainThread) pgcli.pgexecute ERROR - sql: "SELECT * FROM device_device WHERE user_id = '", error: SyntaxError('unterminated quoted string at or near "\'"\nLINE 1: SELECT * FROM device_device WHERE user_id = \'\n                                                    ^\n')
2020-08-05 11:40:13,896 (57597/MainThread) pgcli.pgexecute ERROR - traceback: 'Traceback (most recent call last):\n  File "/usr/local/Cellar/pgcli/2.2.0_1/libexec/lib/python3.8/site-packages/pgcli/pgexecute.py", line 413, in run\n    yield self.execute_normal_sql(sql) + (sql, True, False)\n  File "/usr/local/Cellar/pgcli/2.2.0_1/libexec/lib/python3.8/site-packages/pgcli/pgexecute.py", line 448, in execute_normal_sql\n    cur.execute(split_sql)\npsycopg2.errors.SyntaxError: unterminated quoted string at or near "\'"\nLINE 1: SELECT * FROM device_device WHERE user_id = \'\n                                                    ^\n\n'
2020-09-13 23:19:00,853 (49932/MainThread) pgcli.main INFO - Default pager found in PAGER environment variable: "less"
2020-09-13 23:19:00,855 (49932/MainThread) pgcli.main WARNING - import keyring failed: ModuleNotFoundError("No module named 'keyring'").
2020-09-13 23:19:01,365 (49932/MainThread) pgcli.main ERROR - traceback: 'Traceback (most recent call last):\n  File "/usr/local/Cellar/pgcli/3.0.0/libexec/lib/python3.8/site-packages/pgcli/main.py", line 562, in connect\n    raise e\n  File "/usr/local/Cellar/pgcli/3.0.0/libexec/lib/python3.8/site-packages/pgcli/main.py", line 549, in connect\n    pgexecute = PGExecute(database, user, passwd, host, port, dsn, **kwargs)\n  File "/usr/local/Cellar/pgcli/3.0.0/libexec/lib/python3.8/site-packages/pgcli/pgexecute.py", line 214, in __init__\n    self.connect(database, user, password, host, port, dsn, **kwargs)\n  File "/usr/local/Cellar/pgcli/3.0.0/libexec/lib/python3.8/site-packages/pgcli/pgexecute.py", line 254, in connect\n    conn = psycopg2.connect(**conn_params)\n  File "/usr/local/Cellar/pgcli/3.0.0/libexec/lib/python3.8/site-packages/psycopg2/__init__.py", line 127, in connect\n    conn = _connect(dsn, connection_factory=connection_factory, **kwasync)\npsycopg2.OperationalError: could not translate host name "localhost:5432" to address: nodename nor servname provided, or not known\n\n'
2020-09-13 23:20:13,665 (49996/MainThread) pgcli.main INFO - Default pager found in PAGER environment variable: "less"
2020-09-13 23:20:13,666 (49996/MainThread) pgcli.main WARNING - import keyring failed: ModuleNotFoundError("No module named 'keyring'").
2020-09-13 23:20:13,678 (49996/MainThread) pgcli.main ERROR - traceback: 'Traceback (most recent call last):\n  File "/usr/local/Cellar/pgcli/3.0.0/libexec/lib/python3.8/site-packages/pgcli/main.py", line 562, in connect\n    raise e\n  File "/usr/local/Cellar/pgcli/3.0.0/libexec/lib/python3.8/site-packages/pgcli/main.py", line 549, in connect\n    pgexecute = PGExecute(database, user, passwd, host, port, dsn, **kwargs)\n  File "/usr/local/Cellar/pgcli/3.0.0/libexec/lib/python3.8/site-packages/pgcli/pgexecute.py", line 214, in __init__\n    self.connect(database, user, password, host, port, dsn, **kwargs)\n  File "/usr/local/Cellar/pgcli/3.0.0/libexec/lib/python3.8/site-packages/pgcli/pgexecute.py", line 254, in connect\n    conn = psycopg2.connect(**conn_params)\n  File "/usr/local/Cellar/pgcli/3.0.0/libexec/lib/python3.8/site-packages/psycopg2/__init__.py", line 127, in connect\n    conn = _connect(dsn, connection_factory=connection_factory, **kwasync)\n  File "/usr/local/Cellar/pgcli/3.0.0/libexec/lib/python3.8/site-packages/pgcli/pgexecute.py", line 39, in _wait_select\n    state = conn.poll()\npsycopg2.OperationalError: could not connect to server: Connection refused\n\tIs the server running on host "localhost" (::1) and accepting\n\tTCP/IP connections on port 5432?\ncould not connect to server: Connection refused\n\tIs the server running on host "localhost" (127.0.0.1) and accepting\n\tTCP/IP connections on port 5432?\n\n'
2020-09-29 12:33:21,577 (77506/MainThread) pgcli.main INFO - Default pager found in PAGER environment variable: "less"
2020-09-29 12:33:21,578 (77506/MainThread) pgcli.main WARNING - import keyring failed: ModuleNotFoundError("No module named 'keyring'").
2020-09-29 12:33:21,608 (77506/MainThread) pgcli.main ERROR - traceback: 'Traceback (most recent call last):\n  File "/usr/local/Cellar/pgcli/3.0.0/libexec/lib/python3.8/site-packages/pgcli/main.py", line 562, in connect\n    raise e\n  File "/usr/local/Cellar/pgcli/3.0.0/libexec/lib/python3.8/site-packages/pgcli/main.py", line 549, in connect\n    pgexecute = PGExecute(database, user, passwd, host, port, dsn, **kwargs)\n  File "/usr/local/Cellar/pgcli/3.0.0/libexec/lib/python3.8/site-packages/pgcli/pgexecute.py", line 214, in __init__\n    self.connect(database, user, password, host, port, dsn, **kwargs)\n  File "/usr/local/Cellar/pgcli/3.0.0/libexec/lib/python3.8/site-packages/pgcli/pgexecute.py", line 254, in connect\n    conn = psycopg2.connect(**conn_params)\n  File "/usr/local/Cellar/pgcli/3.0.0/libexec/lib/python3.8/site-packages/psycopg2/__init__.py", line 127, in connect\n    conn = _connect(dsn, connection_factory=connection_factory, **kwasync)\npsycopg2.OperationalError: could not connect to server: No such file or directory\n\tIs the server running locally and accepting\n\tconnections on Unix domain socket "/tmp/.s.PGSQL.5432"?\n\n'
2020-09-29 12:35:06,600 (77530/MainThread) pgcli.main INFO - Default pager found in PAGER environment variable: "less"
2020-09-29 12:35:06,601 (77530/MainThread) pgcli.main WARNING - import keyring failed: ModuleNotFoundError("No module named 'keyring'").
2020-09-29 12:35:14,091 (77530/MainThread) pgcli.main ERROR - traceback: 'Traceback (most recent call last):\n  File "/usr/local/Cellar/pgcli/3.0.0/libexec/lib/python3.8/site-packages/pgcli/main.py", line 562, in connect\n    raise e\n  File "/usr/local/Cellar/pgcli/3.0.0/libexec/lib/python3.8/site-packages/pgcli/main.py", line 549, in connect\n    pgexecute = PGExecute(database, user, passwd, host, port, dsn, **kwargs)\n  File "/usr/local/Cellar/pgcli/3.0.0/libexec/lib/python3.8/site-packages/pgcli/pgexecute.py", line 214, in __init__\n    self.connect(database, user, password, host, port, dsn, **kwargs)\n  File "/usr/local/Cellar/pgcli/3.0.0/libexec/lib/python3.8/site-packages/pgcli/pgexecute.py", line 254, in connect\n    conn = psycopg2.connect(**conn_params)\n  File "/usr/local/Cellar/pgcli/3.0.0/libexec/lib/python3.8/site-packages/psycopg2/__init__.py", line 127, in connect\n    conn = _connect(dsn, connection_factory=connection_factory, **kwasync)\npsycopg2.OperationalError: could not translate host name "http://qa-notify-me.cluster-cqwq02elhn0j.us-east-1.rds.amazonaws.com" to address: nodename nor servname provided, or not known\n\n'
2020-09-29 12:35:32,518 (77536/MainThread) pgcli.main INFO - Default pager found in PAGER environment variable: "less"
2020-09-29 12:35:32,519 (77536/MainThread) pgcli.main WARNING - import keyring failed: ModuleNotFoundError("No module named 'keyring'").
2020-09-29 12:35:35,323 (77536/MainThread) pgcli.main ERROR - traceback: 'Traceback (most recent call last):\n  File "/usr/local/Cellar/pgcli/3.0.0/libexec/lib/python3.8/site-packages/pgcli/main.py", line 562, in connect\n    raise e\n  File "/usr/local/Cellar/pgcli/3.0.0/libexec/lib/python3.8/site-packages/pgcli/main.py", line 549, in connect\n    pgexecute = PGExecute(database, user, passwd, host, port, dsn, **kwargs)\n  File "/usr/local/Cellar/pgcli/3.0.0/libexec/lib/python3.8/site-packages/pgcli/pgexecute.py", line 214, in __init__\n    self.connect(database, user, password, host, port, dsn, **kwargs)\n  File "/usr/local/Cellar/pgcli/3.0.0/libexec/lib/python3.8/site-packages/pgcli/pgexecute.py", line 254, in connect\n    conn = psycopg2.connect(**conn_params)\n  File "/usr/local/Cellar/pgcli/3.0.0/libexec/lib/python3.8/site-packages/psycopg2/__init__.py", line 127, in connect\n    conn = _connect(dsn, connection_factory=connection_factory, **kwasync)\npsycopg2.OperationalError: could not translate host name "http://qa-notify-me.cluster-cqwq02elhn0j.us-east-1.rds.amazonaws.com" to address: nodename nor servname provided, or not known\n\n'
2020-09-29 12:36:11,617 (77540/MainThread) pgcli.main INFO - Default pager found in PAGER environment variable: "less"
2020-09-29 12:36:11,617 (77540/MainThread) pgcli.main WARNING - import keyring failed: ModuleNotFoundError("No module named 'keyring'").
2020-09-29 12:36:13,123 (77540/MainThread) pgcli.main ERROR - traceback: 'Traceback (most recent call last):\n  File "/usr/local/Cellar/pgcli/3.0.0/libexec/lib/python3.8/site-packages/pgcli/main.py", line 562, in connect\n    raise e\n  File "/usr/local/Cellar/pgcli/3.0.0/libexec/lib/python3.8/site-packages/pgcli/main.py", line 549, in connect\n    pgexecute = PGExecute(database, user, passwd, host, port, dsn, **kwargs)\n  File "/usr/local/Cellar/pgcli/3.0.0/libexec/lib/python3.8/site-packages/pgcli/pgexecute.py", line 214, in __init__\n    self.connect(database, user, password, host, port, dsn, **kwargs)\n  File "/usr/local/Cellar/pgcli/3.0.0/libexec/lib/python3.8/site-packages/pgcli/pgexecute.py", line 254, in connect\n    conn = psycopg2.connect(**conn_params)\n  File "/usr/local/Cellar/pgcli/3.0.0/libexec/lib/python3.8/site-packages/psycopg2/__init__.py", line 127, in connect\n    conn = _connect(dsn, connection_factory=connection_factory, **kwasync)\npsycopg2.OperationalError: could not translate host name "http://qa-notify-me.cluster-cqwq02elhn0j.us-east-1.rds.amazonaws.com" to address: nodename nor servname provided, or not known\n\n'
2020-09-29 12:36:45,040 (77548/MainThread) pgcli.main INFO - Default pager found in PAGER environment variable: "less"
2020-09-29 12:36:45,040 (77548/MainThread) pgcli.main WARNING - import keyring failed: ModuleNotFoundError("No module named 'keyring'").
2020-09-29 12:36:46,544 (77548/MainThread) pgcli.main ERROR - traceback: 'Traceback (most recent call last):\n  File "/usr/local/Cellar/pgcli/3.0.0/libexec/lib/python3.8/site-packages/pgcli/main.py", line 562, in connect\n    raise e\n  File "/usr/local/Cellar/pgcli/3.0.0/libexec/lib/python3.8/site-packages/pgcli/main.py", line 549, in connect\n    pgexecute = PGExecute(database, user, passwd, host, port, dsn, **kwargs)\n  File "/usr/local/Cellar/pgcli/3.0.0/libexec/lib/python3.8/site-packages/pgcli/pgexecute.py", line 214, in __init__\n    self.connect(database, user, password, host, port, dsn, **kwargs)\n  File "/usr/local/Cellar/pgcli/3.0.0/libexec/lib/python3.8/site-packages/pgcli/pgexecute.py", line 254, in connect\n    conn = psycopg2.connect(**conn_params)\n  File "/usr/local/Cellar/pgcli/3.0.0/libexec/lib/python3.8/site-packages/psycopg2/__init__.py", line 127, in connect\n    conn = _connect(dsn, connection_factory=connection_factory, **kwasync)\npsycopg2.OperationalError: could not translate host name "http://qa-notify-me.cluster-cqwq02elhn0j.us-east-1.rds.amazonaws.com" to address: nodename nor servname provided, or not known\n\n'
2020-09-29 12:40:50,159 (77603/MainThread) pgcli.main INFO - Default pager found in PAGER environment variable: "less"
2020-09-29 12:40:50,159 (77603/MainThread) pgcli.main WARNING - import keyring failed: ModuleNotFoundError("No module named 'keyring'").
2020-09-29 12:41:00,899 (77603/MainThread) pgcli.main ERROR - traceback: 'Traceback (most recent call last):\n  File "/usr/local/Cellar/pgcli/3.0.0/libexec/lib/python3.8/site-packages/pgcli/main.py", line 549, in connect\n    pgexecute = PGExecute(database, user, passwd, host, port, dsn, **kwargs)\n  File "/usr/local/Cellar/pgcli/3.0.0/libexec/lib/python3.8/site-packages/pgcli/pgexecute.py", line 214, in __init__\n    self.connect(database, user, password, host, port, dsn, **kwargs)\n  File "/usr/local/Cellar/pgcli/3.0.0/libexec/lib/python3.8/site-packages/pgcli/pgexecute.py", line 254, in connect\n    conn = psycopg2.connect(**conn_params)\n  File "/usr/local/Cellar/pgcli/3.0.0/libexec/lib/python3.8/site-packages/psycopg2/__init__.py", line 127, in connect\n    conn = _connect(dsn, connection_factory=connection_factory, **kwasync)\n  File "/usr/local/Cellar/pgcli/3.0.0/libexec/lib/python3.8/site-packages/pgcli/pgexecute.py", line 39, in _wait_select\n    state = conn.poll()\npsycopg2.OperationalError: FATAL:  password authentication failed for user "sername"\nFATAL:  password authentication failed for user "sername"\n\n\nDuring handling of the above exception, another exception occurred:\n\nTraceback (most recent call last):\n  File "/usr/local/Cellar/pgcli/3.0.0/libexec/lib/python3.8/site-packages/pgcli/main.py", line 558, in connect\n    pgexecute = PGExecute(\n  File "/usr/local/Cellar/pgcli/3.0.0/libexec/lib/python3.8/site-packages/pgcli/pgexecute.py", line 214, in __init__\n    self.connect(database, user, password, host, port, dsn, **kwargs)\n  File "/usr/local/Cellar/pgcli/3.0.0/libexec/lib/python3.8/site-packages/pgcli/pgexecute.py", line 254, in connect\n    conn = psycopg2.connect(**conn_params)\n  File "/usr/local/Cellar/pgcli/3.0.0/libexec/lib/python3.8/site-packages/psycopg2/__init__.py", line 127, in connect\n    conn = _connect(dsn, connection_factory=connection_factory, **kwasync)\n  File "/usr/local/Cellar/pgcli/3.0.0/libexec/lib/python3.8/site-packages/pgcli/pgexecute.py", line 39, in _wait_select\n    state = conn.poll()\npsycopg2.OperationalError: FATAL:  password authentication failed for user "sername"\nFATAL:  password authentication failed for user "sername"\n\n'
2020-09-29 12:41:25,086 (77608/MainThread) pgcli.main INFO - Default pager found in PAGER environment variable: "less"
2020-09-29 12:41:25,087 (77608/MainThread) pgcli.main WARNING - import keyring failed: ModuleNotFoundError("No module named 'keyring'").
2020-09-29 12:43:03,406 (77608/MainThread) pgcli.pgexecute ERROR - sql: 'SELECT * FROM notify_notification WHERE id = "3ec63b05-94e9-4590-bb19-e1edb095fc06"', error: UndefinedColumn('column "3ec63b05-94e9-4590-bb19-e1edb095fc06" does not exist\nLINE 1: SELECT * FROM notify_notification WHERE id = "3ec63b05-94e9-...\n                                                     ^\n')
2020-09-29 12:43:03,409 (77608/MainThread) pgcli.pgexecute ERROR - traceback: 'Traceback (most recent call last):\n  File "/usr/local/Cellar/pgcli/3.0.0/libexec/lib/python3.8/site-packages/pgcli/pgexecute.py", line 409, in run\n    yield self.execute_normal_sql(sql) + (sql, True, False)\n  File "/usr/local/Cellar/pgcli/3.0.0/libexec/lib/python3.8/site-packages/pgcli/pgexecute.py", line 444, in execute_normal_sql\n    cur.execute(split_sql)\npsycopg2.errors.UndefinedColumn: column "3ec63b05-94e9-4590-bb19-e1edb095fc06" does not exist\nLINE 1: SELECT * FROM notify_notification WHERE id = "3ec63b05-94e9-...\n                                                     ^\n\n'
2020-09-29 12:43:07,685 (77608/MainThread) pgcli.pgexecute ERROR - sql: 'SELECT * FROM notify_notification WHERE id = "3ec63b05-94e9-4590-bb19-e1edb095fc06"', error: UndefinedColumn('column "3ec63b05-94e9-4590-bb19-e1edb095fc06" does not exist\nLINE 1: SELECT * FROM notify_notification WHERE id = "3ec63b05-94e9-...\n                                                     ^\n')
2020-09-29 12:43:07,686 (77608/MainThread) pgcli.pgexecute ERROR - traceback: 'Traceback (most recent call last):\n  File "/usr/local/Cellar/pgcli/3.0.0/libexec/lib/python3.8/site-packages/pgcli/pgexecute.py", line 409, in run\n    yield self.execute_normal_sql(sql) + (sql, True, False)\n  File "/usr/local/Cellar/pgcli/3.0.0/libexec/lib/python3.8/site-packages/pgcli/pgexecute.py", line 444, in execute_normal_sql\n    cur.execute(split_sql)\npsycopg2.errors.UndefinedColumn: column "3ec63b05-94e9-4590-bb19-e1edb095fc06" does not exist\nLINE 1: SELECT * FROM notify_notification WHERE id = "3ec63b05-94e9-...\n                                                     ^\n\n'
2020-09-29 12:43:20,983 (77608/MainThread) pgcli.pgexecute ERROR - sql: 'SELECT * FROM notify_notification WHERE id = 3ec63b05-94e9-4590-bb19-e1edb095fc06', error: SyntaxError('syntax error at or near "ec63b05"\nLINE 1: SELECT * FROM notify_notification WHERE id = 3ec63b05-94e9-4...\n                                                      ^\n')
2020-09-29 12:43:20,984 (77608/MainThread) pgcli.pgexecute ERROR - traceback: 'Traceback (most recent call last):\n  File "/usr/local/Cellar/pgcli/3.0.0/libexec/lib/python3.8/site-packages/pgcli/pgexecute.py", line 409, in run\n    yield self.execute_normal_sql(sql) + (sql, True, False)\n  File "/usr/local/Cellar/pgcli/3.0.0/libexec/lib/python3.8/site-packages/pgcli/pgexecute.py", line 444, in execute_normal_sql\n    cur.execute(split_sql)\npsycopg2.errors.SyntaxError: syntax error at or near "ec63b05"\nLINE 1: SELECT * FROM notify_notification WHERE id = 3ec63b05-94e9-4...\n                                                      ^\n\n'
2020-09-29 12:43:38,075 (77608/MainThread) pgcli.pgexecute ERROR - sql: 'SELECT * FROM notify_notification WHERE id="3ec63b05-94e9-4590-bb19-e1edb095fc06"', error: UndefinedColumn('column "3ec63b05-94e9-4590-bb19-e1edb095fc06" does not exist\nLINE 1: SELECT * FROM notify_notification WHERE id="3ec63b05-94e9-45...\n                                                   ^\n')
2020-09-29 12:43:38,075 (77608/MainThread) pgcli.pgexecute ERROR - traceback: 'Traceback (most recent call last):\n  File "/usr/local/Cellar/pgcli/3.0.0/libexec/lib/python3.8/site-packages/pgcli/pgexecute.py", line 409, in run\n    yield self.execute_normal_sql(sql) + (sql, True, False)\n  File "/usr/local/Cellar/pgcli/3.0.0/libexec/lib/python3.8/site-packages/pgcli/pgexecute.py", line 444, in execute_normal_sql\n    cur.execute(split_sql)\npsycopg2.errors.UndefinedColumn: column "3ec63b05-94e9-4590-bb19-e1edb095fc06" does not exist\nLINE 1: SELECT * FROM notify_notification WHERE id="3ec63b05-94e9-45...\n                                                   ^\n\n'
2020-09-29 12:44:22,751 (77608/MainThread) pgcli.pgexecute ERROR - sql: 'SELECT * FROM notify_notification WHERE', error: SyntaxError('syntax error at end of input\nLINE 1: SELECT * FROM notify_notification WHERE\n                                               ^\n')
2020-09-29 12:44:22,752 (77608/MainThread) pgcli.pgexecute ERROR - traceback: 'Traceback (most recent call last):\n  File "/usr/local/Cellar/pgcli/3.0.0/libexec/lib/python3.8/site-packages/pgcli/pgexecute.py", line 409, in run\n    yield self.execute_normal_sql(sql) + (sql, True, False)\n  File "/usr/local/Cellar/pgcli/3.0.0/libexec/lib/python3.8/site-packages/pgcli/pgexecute.py", line 444, in execute_normal_sql\n    cur.execute(split_sql)\npsycopg2.errors.SyntaxError: syntax error at end of input\nLINE 1: SELECT * FROM notify_notification WHERE\n                                               ^\n\n'
2020-09-29 12:44:37,192 (77608/MainThread) pgcli.pgexecute ERROR - sql: 'SELECT * FROM notify_notification WHERE', error: SyntaxError('syntax error at end of input\nLINE 1: SELECT * FROM notify_notification WHERE\n                                               ^\n')
2020-09-29 12:44:37,193 (77608/MainThread) pgcli.pgexecute ERROR - traceback: 'Traceback (most recent call last):\n  File "/usr/local/Cellar/pgcli/3.0.0/libexec/lib/python3.8/site-packages/pgcli/pgexecute.py", line 409, in run\n    yield self.execute_normal_sql(sql) + (sql, True, False)\n  File "/usr/local/Cellar/pgcli/3.0.0/libexec/lib/python3.8/site-packages/pgcli/pgexecute.py", line 444, in execute_normal_sql\n    cur.execute(split_sql)\npsycopg2.errors.SyntaxError: syntax error at end of input\nLINE 1: SELECT * FROM notify_notification WHERE\n                                               ^\n\n'
2020-09-29 12:45:50,863 (77608/MainThread) pgcli.pgexecute ERROR - sql: 'SELECT * FROM information_schema ORDER BY RANDOM() LIMIT 1', error: UndefinedTable('relation "information_schema" does not exist\nLINE 1: SELECT * FROM information_schema ORDER BY RANDOM() LIMIT 1\n                      ^\n')
2020-09-29 12:45:50,863 (77608/MainThread) pgcli.pgexecute ERROR - traceback: 'Traceback (most recent call last):\n  File "/usr/local/Cellar/pgcli/3.0.0/libexec/lib/python3.8/site-packages/pgcli/pgexecute.py", line 409, in run\n    yield self.execute_normal_sql(sql) + (sql, True, False)\n  File "/usr/local/Cellar/pgcli/3.0.0/libexec/lib/python3.8/site-packages/pgcli/pgexecute.py", line 444, in execute_normal_sql\n    cur.execute(split_sql)\npsycopg2.errors.UndefinedTable: relation "information_schema" does not exist\nLINE 1: SELECT * FROM information_schema ORDER BY RANDOM() LIMIT 1\n                      ^\n\n'
2020-09-29 12:46:59,660 (77608/MainThread) pgcli.pgexecute ERROR - sql: 'SELECT * FROM notify_notification WHERE id="3ec63b05-94e9-4590-bb19-e1edb095fc06"', error: UndefinedColumn('column "3ec63b05-94e9-4590-bb19-e1edb095fc06" does not exist\nLINE 1: SELECT * FROM notify_notification WHERE id="3ec63b05-94e9-45...\n                                                   ^\n')
2020-09-29 12:46:59,662 (77608/MainThread) pgcli.pgexecute ERROR - traceback: 'Traceback (most recent call last):\n  File "/usr/local/Cellar/pgcli/3.0.0/libexec/lib/python3.8/site-packages/pgcli/pgexecute.py", line 409, in run\n    yield self.execute_normal_sql(sql) + (sql, True, False)\n  File "/usr/local/Cellar/pgcli/3.0.0/libexec/lib/python3.8/site-packages/pgcli/pgexecute.py", line 444, in execute_normal_sql\n    cur.execute(split_sql)\npsycopg2.errors.UndefinedColumn: column "3ec63b05-94e9-4590-bb19-e1edb095fc06" does not exist\nLINE 1: SELECT * FROM notify_notification WHERE id="3ec63b05-94e9-45...\n                                                   ^\n\n'
2020-09-29 12:47:37,345 (77608/MainThread) pgcli.pgexecute ERROR - sql: 'SELECT * FROM notify_notification WHERE id="3ec63b05-94e9-4590-bb19-e1edb095fc06"', error: UndefinedColumn('column "3ec63b05-94e9-4590-bb19-e1edb095fc06" does not exist\nLINE 1: SELECT * FROM notify_notification WHERE id="3ec63b05-94e9-45...\n                                                   ^\n')
2020-09-29 12:47:37,345 (77608/MainThread) pgcli.pgexecute ERROR - traceback: 'Traceback (most recent call last):\n  File "/usr/local/Cellar/pgcli/3.0.0/libexec/lib/python3.8/site-packages/pgcli/pgexecute.py", line 409, in run\n    yield self.execute_normal_sql(sql) + (sql, True, False)\n  File "/usr/local/Cellar/pgcli/3.0.0/libexec/lib/python3.8/site-packages/pgcli/pgexecute.py", line 444, in execute_normal_sql\n    cur.execute(split_sql)\npsycopg2.errors.UndefinedColumn: column "3ec63b05-94e9-4590-bb19-e1edb095fc06" does not exist\nLINE 1: SELECT * FROM notify_notification WHERE id="3ec63b05-94e9-45...\n                                                   ^\n\n'
2020-09-29 12:47:46,587 (77608/MainThread) pgcli.pgexecute ERROR - sql: 'SELECT * FROM notify_notification WHERE id = "3ec63b05-94e9-4590-bb19-e1edb095fc06"', error: UndefinedColumn('column "3ec63b05-94e9-4590-bb19-e1edb095fc06" does not exist\nLINE 1: SELECT * FROM notify_notification WHERE id = "3ec63b05-94e9-...\n                                                     ^\n')
2020-09-29 12:47:46,588 (77608/MainThread) pgcli.pgexecute ERROR - traceback: 'Traceback (most recent call last):\n  File "/usr/local/Cellar/pgcli/3.0.0/libexec/lib/python3.8/site-packages/pgcli/pgexecute.py", line 409, in run\n    yield self.execute_normal_sql(sql) + (sql, True, False)\n  File "/usr/local/Cellar/pgcli/3.0.0/libexec/lib/python3.8/site-packages/pgcli/pgexecute.py", line 444, in execute_normal_sql\n    cur.execute(split_sql)\npsycopg2.errors.UndefinedColumn: column "3ec63b05-94e9-4590-bb19-e1edb095fc06" does not exist\nLINE 1: SELECT * FROM notify_notification WHERE id = "3ec63b05-94e9-...\n                                                     ^\n\n'
2020-09-29 12:48:00,943 (77608/MainThread) pgcli.pgexecute ERROR - sql: 'SELECT * FROM notify_notification WHERE id = "117bdfa0-d5a8-482d-aed4-b59e57185e3f"', error: UndefinedColumn('column "117bdfa0-d5a8-482d-aed4-b59e57185e3f" does not exist\nLINE 1: SELECT * FROM notify_notification WHERE id = "117bdfa0-d5a8-...\n                                                     ^\n')
2020-09-29 12:48:00,944 (77608/MainThread) pgcli.pgexecute ERROR - traceback: 'Traceback (most recent call last):\n  File "/usr/local/Cellar/pgcli/3.0.0/libexec/lib/python3.8/site-packages/pgcli/pgexecute.py", line 409, in run\n    yield self.execute_normal_sql(sql) + (sql, True, False)\n  File "/usr/local/Cellar/pgcli/3.0.0/libexec/lib/python3.8/site-packages/pgcli/pgexecute.py", line 444, in execute_normal_sql\n    cur.execute(split_sql)\npsycopg2.errors.UndefinedColumn: column "117bdfa0-d5a8-482d-aed4-b59e57185e3f" does not exist\nLINE 1: SELECT * FROM notify_notification WHERE id = "117bdfa0-d5a8-...\n                                                     ^\n\n'
2020-09-30 18:42:52,089 (18984/MainThread) pgcli.main INFO - Default pager found in PAGER environment variable: "less"
2020-09-30 18:42:52,090 (18984/MainThread) pgcli.main WARNING - import keyring failed: ModuleNotFoundError("No module named 'keyring'").
2020-09-30 18:43:00,438 (18984/MainThread) pgcli.main ERROR - traceback: 'Traceback (most recent call last):\n  File "/usr/local/Cellar/pgcli/3.0.0/libexec/lib/python3.8/site-packages/pgcli/main.py", line 562, in connect\n    raise e\n  File "/usr/local/Cellar/pgcli/3.0.0/libexec/lib/python3.8/site-packages/pgcli/main.py", line 549, in connect\n    pgexecute = PGExecute(database, user, passwd, host, port, dsn, **kwargs)\n  File "/usr/local/Cellar/pgcli/3.0.0/libexec/lib/python3.8/site-packages/pgcli/pgexecute.py", line 214, in __init__\n    self.connect(database, user, password, host, port, dsn, **kwargs)\n  File "/usr/local/Cellar/pgcli/3.0.0/libexec/lib/python3.8/site-packages/pgcli/pgexecute.py", line 254, in connect\n    conn = psycopg2.connect(**conn_params)\n  File "/usr/local/Cellar/pgcli/3.0.0/libexec/lib/python3.8/site-packages/psycopg2/__init__.py", line 127, in connect\n    conn = _connect(dsn, connection_factory=connection_factory, **kwasync)\n  File "/usr/local/Cellar/pgcli/3.0.0/libexec/lib/python3.8/site-packages/pgcli/pgexecute.py", line 39, in _wait_select\n    state = conn.poll()\npsycopg2.OperationalError: FATAL:  database "staging-notify_me_db" does not exist\n\n'
2020-09-30 18:43:17,447 (18987/MainThread) pgcli.main INFO - Default pager found in PAGER environment variable: "less"
2020-09-30 18:43:17,448 (18987/MainThread) pgcli.main WARNING - import keyring failed: ModuleNotFoundError("No module named 'keyring'").
2020-09-30 18:43:19,087 (18987/MainThread) pgcli.main ERROR - traceback: 'Traceback (most recent call last):\n  File "/usr/local/Cellar/pgcli/3.0.0/libexec/lib/python3.8/site-packages/pgcli/main.py", line 562, in connect\n    raise e\n  File "/usr/local/Cellar/pgcli/3.0.0/libexec/lib/python3.8/site-packages/pgcli/main.py", line 549, in connect\n    pgexecute = PGExecute(database, user, passwd, host, port, dsn, **kwargs)\n  File "/usr/local/Cellar/pgcli/3.0.0/libexec/lib/python3.8/site-packages/pgcli/pgexecute.py", line 214, in __init__\n    self.connect(database, user, password, host, port, dsn, **kwargs)\n  File "/usr/local/Cellar/pgcli/3.0.0/libexec/lib/python3.8/site-packages/pgcli/pgexecute.py", line 254, in connect\n    conn = psycopg2.connect(**conn_params)\n  File "/usr/local/Cellar/pgcli/3.0.0/libexec/lib/python3.8/site-packages/psycopg2/__init__.py", line 127, in connect\n    conn = _connect(dsn, connection_factory=connection_factory, **kwasync)\n  File "/usr/local/Cellar/pgcli/3.0.0/libexec/lib/python3.8/site-packages/pgcli/pgexecute.py", line 39, in _wait_select\n    state = conn.poll()\npsycopg2.OperationalError: FATAL:  database "staging-notify-me-db" does not exist\n\n'
2020-09-30 18:43:24,512 (18990/MainThread) pgcli.main INFO - Default pager found in PAGER environment variable: "less"
2020-09-30 18:43:24,512 (18990/MainThread) pgcli.main WARNING - import keyring failed: ModuleNotFoundError("No module named 'keyring'").
2020-09-30 18:43:26,439 (18990/MainThread) pgcli.main ERROR - traceback: 'Traceback (most recent call last):\n  File "/usr/local/Cellar/pgcli/3.0.0/libexec/lib/python3.8/site-packages/pgcli/main.py", line 562, in connect\n    raise e\n  File "/usr/local/Cellar/pgcli/3.0.0/libexec/lib/python3.8/site-packages/pgcli/main.py", line 549, in connect\n    pgexecute = PGExecute(database, user, passwd, host, port, dsn, **kwargs)\n  File "/usr/local/Cellar/pgcli/3.0.0/libexec/lib/python3.8/site-packages/pgcli/pgexecute.py", line 214, in __init__\n    self.connect(database, user, password, host, port, dsn, **kwargs)\n  File "/usr/local/Cellar/pgcli/3.0.0/libexec/lib/python3.8/site-packages/pgcli/pgexecute.py", line 254, in connect\n    conn = psycopg2.connect(**conn_params)\n  File "/usr/local/Cellar/pgcli/3.0.0/libexec/lib/python3.8/site-packages/psycopg2/__init__.py", line 127, in connect\n    conn = _connect(dsn, connection_factory=connection_factory, **kwasync)\n  File "/usr/local/Cellar/pgcli/3.0.0/libexec/lib/python3.8/site-packages/pgcli/pgexecute.py", line 39, in _wait_select\n    state = conn.poll()\npsycopg2.OperationalError: FATAL:  database "staging-notify-me-db" does not exist\n\n'
2020-09-30 18:43:41,514 (18997/MainThread) pgcli.main INFO - Default pager found in PAGER environment variable: "less"
2020-09-30 18:43:41,514 (18997/MainThread) pgcli.main WARNING - import keyring failed: ModuleNotFoundError("No module named 'keyring'").
2020-09-30 18:43:43,179 (18997/MainThread) pgcli.main ERROR - traceback: 'Traceback (most recent call last):\n  File "/usr/local/Cellar/pgcli/3.0.0/libexec/lib/python3.8/site-packages/pgcli/main.py", line 562, in connect\n    raise e\n  File "/usr/local/Cellar/pgcli/3.0.0/libexec/lib/python3.8/site-packages/pgcli/main.py", line 549, in connect\n    pgexecute = PGExecute(database, user, passwd, host, port, dsn, **kwargs)\n  File "/usr/local/Cellar/pgcli/3.0.0/libexec/lib/python3.8/site-packages/pgcli/pgexecute.py", line 214, in __init__\n    self.connect(database, user, password, host, port, dsn, **kwargs)\n  File "/usr/local/Cellar/pgcli/3.0.0/libexec/lib/python3.8/site-packages/pgcli/pgexecute.py", line 254, in connect\n    conn = psycopg2.connect(**conn_params)\n  File "/usr/local/Cellar/pgcli/3.0.0/libexec/lib/python3.8/site-packages/psycopg2/__init__.py", line 127, in connect\n    conn = _connect(dsn, connection_factory=connection_factory, **kwasync)\n  File "/usr/local/Cellar/pgcli/3.0.0/libexec/lib/python3.8/site-packages/pgcli/pgexecute.py", line 39, in _wait_select\n    state = conn.poll()\npsycopg2.OperationalError: FATAL:  database "staging_notify_me_db" does not exist\n\n'
2020-09-30 18:44:47,668 (19010/MainThread) pgcli.main INFO - Default pager found in PAGER environment variable: "less"
2020-09-30 18:44:47,669 (19010/MainThread) pgcli.main WARNING - import keyring failed: ModuleNotFoundError("No module named 'keyring'").
2020-09-30 18:45:25,354 (19010/MainThread) pgcli.pgexecute ERROR - sql: 'select isscheduleactive(\n    start_date    := ,\n    end_date      := ,\n    shift_id      := ,\n    period        := ,\n    start_day_idx := ,\n    monday_hrs    := ,\n    tuesday_hrs   := ,\n    wednesday_hrs := ,\n    thursday_hrs  := ,\n    friday_hrs    := ,\n    saturday_hrs  := ,\n    sunday_hrs    := ,\n    schedule_id   := ,\n    p_target      := ,\n    p_tim', error: SyntaxError('syntax error at or near ","\nLINE 2:     start_date    := ,\n                             ^\n')
2020-09-30 18:45:25,356 (19010/MainThread) pgcli.pgexecute ERROR - traceback: 'Traceback (most recent call last):\n  File "/usr/local/Cellar/pgcli/3.0.0/libexec/lib/python3.8/site-packages/pgcli/pgexecute.py", line 409, in run\n    yield self.execute_normal_sql(sql) + (sql, True, False)\n  File "/usr/local/Cellar/pgcli/3.0.0/libexec/lib/python3.8/site-packages/pgcli/pgexecute.py", line 444, in execute_normal_sql\n    cur.execute(split_sql)\npsycopg2.errors.SyntaxError: syntax error at or near ","\nLINE 2:     start_date    := ,\n                             ^\n\n'
2020-09-30 18:47:23,304 (19010/MainThread) pgcli.main ERROR - sql: 'select * from user_profile_user_user_permissions ', error: StopIteration()
2020-09-30 18:47:23,306 (19010/MainThread) pgcli.main ERROR - traceback: 'Traceback (most recent call last):\n  File "/usr/local/Cellar/pgcli/3.0.0/libexec/lib/python3.8/site-packages/pgcli/main.py", line 634, in execute_command\n    output, query = self._evaluate_command(text)\n  File "/usr/local/Cellar/pgcli/3.0.0/libexec/lib/python3.8/site-packages/pgcli/main.py", line 909, in _evaluate_command\n    formatted = format_output(title, cur, headers, status, settings)\n  File "/usr/local/Cellar/pgcli/3.0.0/libexec/lib/python3.8/site-packages/pgcli/main.py", line 1432, in format_output\n    first_line = next(formatted)\nStopIteration\n'
2020-09-30 18:47:39,085 (19010/MainThread) pgcli.main ERROR - sql: 'select * from user_profile_user_user_permissions ORDER BY random() LIMIT 1;', error: StopIteration()
2020-09-30 18:47:39,085 (19010/MainThread) pgcli.main ERROR - traceback: 'Traceback (most recent call last):\n  File "/usr/local/Cellar/pgcli/3.0.0/libexec/lib/python3.8/site-packages/pgcli/main.py", line 634, in execute_command\n    output, query = self._evaluate_command(text)\n  File "/usr/local/Cellar/pgcli/3.0.0/libexec/lib/python3.8/site-packages/pgcli/main.py", line 909, in _evaluate_command\n    formatted = format_output(title, cur, headers, status, settings)\n  File "/usr/local/Cellar/pgcli/3.0.0/libexec/lib/python3.8/site-packages/pgcli/main.py", line 1432, in format_output\n    first_line = next(formatted)\nStopIteration\n'
2020-09-30 18:47:45,651 (19010/MainThread) pgcli.main ERROR - sql: 'select * from user_profile_user_user_permissions ORDER BY RANDOM() LIMIT 1;', error: StopIteration()
2020-09-30 18:47:45,651 (19010/MainThread) pgcli.main ERROR - traceback: 'Traceback (most recent call last):\n  File "/usr/local/Cellar/pgcli/3.0.0/libexec/lib/python3.8/site-packages/pgcli/main.py", line 634, in execute_command\n    output, query = self._evaluate_command(text)\n  File "/usr/local/Cellar/pgcli/3.0.0/libexec/lib/python3.8/site-packages/pgcli/main.py", line 909, in _evaluate_command\n    formatted = format_output(title, cur, headers, status, settings)\n  File "/usr/local/Cellar/pgcli/3.0.0/libexec/lib/python3.8/site-packages/pgcli/main.py", line 1432, in format_output\n    first_line = next(formatted)\nStopIteration\n'
2020-09-30 18:47:55,213 (19010/MainThread) pgcli.pgexecute ERROR - sql: 'select * from user_profile_user_permissions ORDER BY RANDOM() LIMIT 1', error: UndefinedTable('relation "user_profile_user_permissions" does not exist\nLINE 1: select * from user_profile_user_permissions ORDER BY RANDOM(...\n                      ^\n')
2020-09-30 18:47:55,213 (19010/MainThread) pgcli.pgexecute ERROR - traceback: 'Traceback (most recent call last):\n  File "/usr/local/Cellar/pgcli/3.0.0/libexec/lib/python3.8/site-packages/pgcli/pgexecute.py", line 409, in run\n    yield self.execute_normal_sql(sql) + (sql, True, False)\n  File "/usr/local/Cellar/pgcli/3.0.0/libexec/lib/python3.8/site-packages/pgcli/pgexecute.py", line 444, in execute_normal_sql\n    cur.execute(split_sql)\npsycopg2.errors.UndefinedTable: relation "user_profile_user_permissions" does not exist\nLINE 1: select * from user_profile_user_permissions ORDER BY RANDOM(...\n                      ^\n\n'
2020-09-30 18:48:46,402 (19010/MainThread) pgcli.main ERROR - sql: 'select * from user_profile_user_user_permissions ORDER BY RANDOM() LIMIT 1;', error: StopIteration()
2020-09-30 18:48:46,402 (19010/MainThread) pgcli.main ERROR - traceback: 'Traceback (most recent call last):\n  File "/usr/local/Cellar/pgcli/3.0.0/libexec/lib/python3.8/site-packages/pgcli/main.py", line 634, in execute_command\n    output, query = self._evaluate_command(text)\n  File "/usr/local/Cellar/pgcli/3.0.0/libexec/lib/python3.8/site-packages/pgcli/main.py", line 909, in _evaluate_command\n    formatted = format_output(title, cur, headers, status, settings)\n  File "/usr/local/Cellar/pgcli/3.0.0/libexec/lib/python3.8/site-packages/pgcli/main.py", line 1432, in format_output\n    first_line = next(formatted)\nStopIteration\n'
2020-09-30 18:48:50,204 (19010/MainThread) pgcli.pgexecute ERROR - sql: 'user_profile_user_user_permissions', error: SyntaxError('syntax error at or near "user_profile_user_user_permissions"\nLINE 1: user_profile_user_user_permissions\n        ^\n')
2020-09-30 18:48:50,205 (19010/MainThread) pgcli.pgexecute ERROR - traceback: 'Traceback (most recent call last):\n  File "/usr/local/Cellar/pgcli/3.0.0/libexec/lib/python3.8/site-packages/pgcli/pgexecute.py", line 409, in run\n    yield self.execute_normal_sql(sql) + (sql, True, False)\n  File "/usr/local/Cellar/pgcli/3.0.0/libexec/lib/python3.8/site-packages/pgcli/pgexecute.py", line 444, in execute_normal_sql\n    cur.execute(split_sql)\npsycopg2.errors.SyntaxError: syntax error at or near "user_profile_user_user_permissions"\nLINE 1: user_profile_user_user_permissions\n        ^\n\n'
2020-09-30 18:48:58,082 (19010/MainThread) pgcli.main ERROR - sql: 'SELECT * FROM user_profile_user_user_permissions ORDER BY RANDOM() LIMIT 1;', error: StopIteration()
2020-09-30 18:48:58,082 (19010/MainThread) pgcli.main ERROR - traceback: 'Traceback (most recent call last):\n  File "/usr/local/Cellar/pgcli/3.0.0/libexec/lib/python3.8/site-packages/pgcli/main.py", line 634, in execute_command\n    output, query = self._evaluate_command(text)\n  File "/usr/local/Cellar/pgcli/3.0.0/libexec/lib/python3.8/site-packages/pgcli/main.py", line 909, in _evaluate_command\n    formatted = format_output(title, cur, headers, status, settings)\n  File "/usr/local/Cellar/pgcli/3.0.0/libexec/lib/python3.8/site-packages/pgcli/main.py", line 1432, in format_output\n    first_line = next(formatted)\nStopIteration\n'
2020-09-30 18:49:10,019 (19010/MainThread) pgcli.main ERROR - sql: 'SELECT * FROM user_profile_user_user_permissions ORDER BY RANDOM() LIMIT 1;', error: StopIteration()
2020-09-30 18:49:10,019 (19010/MainThread) pgcli.main ERROR - traceback: 'Traceback (most recent call last):\n  File "/usr/local/Cellar/pgcli/3.0.0/libexec/lib/python3.8/site-packages/pgcli/main.py", line 634, in execute_command\n    output, query = self._evaluate_command(text)\n  File "/usr/local/Cellar/pgcli/3.0.0/libexec/lib/python3.8/site-packages/pgcli/main.py", line 909, in _evaluate_command\n    formatted = format_output(title, cur, headers, status, settings)\n  File "/usr/local/Cellar/pgcli/3.0.0/libexec/lib/python3.8/site-packages/pgcli/main.py", line 1432, in format_output\n    first_line = next(formatted)\nStopIteration\n'
2020-09-30 20:52:19,397 (19010/MainThread) pgcli.pgexecute ERROR - sql: '/dt', error: SyntaxError('syntax error at or near "/"\nLINE 1: /dt\n        ^\n')
2020-09-30 20:52:19,399 (19010/MainThread) pgcli.pgexecute ERROR - traceback: 'Traceback (most recent call last):\n  File "/usr/local/Cellar/pgcli/3.0.0/libexec/lib/python3.8/site-packages/pgcli/pgexecute.py", line 409, in run\n    yield self.execute_normal_sql(sql) + (sql, True, False)\n  File "/usr/local/Cellar/pgcli/3.0.0/libexec/lib/python3.8/site-packages/pgcli/pgexecute.py", line 444, in execute_normal_sql\n    cur.execute(split_sql)\npsycopg2.errors.SyntaxError: syntax error at or near "/"\nLINE 1: /dt\n        ^\n\n'
2020-09-30 20:52:21,376 (19010/MainThread) pgcli.pgexecute ERROR - sql: '/dt', error: SyntaxError('syntax error at or near "/"\nLINE 1: /dt\n        ^\n')
2020-09-30 20:52:21,376 (19010/MainThread) pgcli.pgexecute ERROR - traceback: 'Traceback (most recent call last):\n  File "/usr/local/Cellar/pgcli/3.0.0/libexec/lib/python3.8/site-packages/pgcli/pgexecute.py", line 409, in run\n    yield self.execute_normal_sql(sql) + (sql, True, False)\n  File "/usr/local/Cellar/pgcli/3.0.0/libexec/lib/python3.8/site-packages/pgcli/pgexecute.py", line 444, in execute_normal_sql\n    cur.execute(split_sql)\npsycopg2.errors.SyntaxError: syntax error at or near "/"\nLINE 1: /dt\n        ^\n\n'
2020-10-02 13:44:07,197 (64808/MainThread) pgcli.main INFO - Default pager found in PAGER environment variable: "less"
2020-10-02 13:44:07,198 (64808/MainThread) pgcli.main WARNING - import keyring failed: ModuleNotFoundError("No module named 'keyring'").
2020-10-02 13:44:28,047 (64810/MainThread) pgcli.main INFO - Default pager found in PAGER environment variable: "less"
2020-10-02 13:44:28,048 (64810/MainThread) pgcli.main WARNING - import keyring failed: ModuleNotFoundError("No module named 'keyring'").
2020-10-02 13:44:47,743 (64810/MainThread) pgcli.pgexecute ERROR - sql: 'select awsdms_intercept_ddl()', error: FeatureNotSupported('trigger functions can only be called as triggers\nCONTEXT:  compilation of PL/pgSQL function "awsdms_intercept_ddl" near line 1\n')
2020-10-02 13:44:47,755 (64810/MainThread) pgcli.pgexecute ERROR - traceback: 'Traceback (most recent call last):\n  File "/usr/local/Cellar/pgcli/3.0.0/libexec/lib/python3.8/site-packages/pgcli/pgexecute.py", line 409, in run\n    yield self.execute_normal_sql(sql) + (sql, True, False)\n  File "/usr/local/Cellar/pgcli/3.0.0/libexec/lib/python3.8/site-packages/pgcli/pgexecute.py", line 444, in execute_normal_sql\n    cur.execute(split_sql)\npsycopg2.errors.FeatureNotSupported: trigger functions can only be called as triggers\nCONTEXT:  compilation of PL/pgSQL function "awsdms_intercept_ddl" near line 1\n\n'
2020-10-02 14:08:51,409 (64810/MainThread) pgcli.pgexecute ERROR - sql: "select * from customer_customeradmin where user_id = '4490527' JOIN on customer_customeradmin_allowed_groups WHERE user_id = customeradmin_id", error: SyntaxError('syntax error at or near "JOIN"\nLINE 1: ... customer_customeradmin where user_id = \'4490527\' JOIN on cu...\n                                                             ^\n')
2020-10-02 14:08:51,412 (64810/MainThread) pgcli.pgexecute ERROR - traceback: 'Traceback (most recent call last):\n  File "/usr/local/Cellar/pgcli/3.0.0/libexec/lib/python3.8/site-packages/pgcli/pgexecute.py", line 409, in run\n    yield self.execute_normal_sql(sql) + (sql, True, False)\n  File "/usr/local/Cellar/pgcli/3.0.0/libexec/lib/python3.8/site-packages/pgcli/pgexecute.py", line 444, in execute_normal_sql\n    cur.execute(split_sql)\npsycopg2.errors.SyntaxError: syntax error at or near "JOIN"\nLINE 1: ... customer_customeradmin where user_id = \'4490527\' JOIN on cu...\n                                                             ^\n\n'
2020-10-02 14:09:31,011 (64810/MainThread) pgcli.pgexecute ERROR - sql: "select * from customer_customeradmin where user_id = '4490527' INNER JOIN on customer_customeradmin_allowed_groups WHERE user_id = customeradmin_id", error: SyntaxError('syntax error at or near "INNER"\nLINE 1: ... customer_customeradmin where user_id = \'4490527\' INNER JOIN...\n                                                             ^\n')
2020-10-02 14:09:31,015 (64810/MainThread) pgcli.pgexecute ERROR - traceback: 'Traceback (most recent call last):\n  File "/usr/local/Cellar/pgcli/3.0.0/libexec/lib/python3.8/site-packages/pgcli/pgexecute.py", line 409, in run\n    yield self.execute_normal_sql(sql) + (sql, True, False)\n  File "/usr/local/Cellar/pgcli/3.0.0/libexec/lib/python3.8/site-packages/pgcli/pgexecute.py", line 444, in execute_normal_sql\n    cur.execute(split_sql)\npsycopg2.errors.SyntaxError: syntax error at or near "INNER"\nLINE 1: ... customer_customeradmin where user_id = \'4490527\' INNER JOIN...\n                                                             ^\n\n'
2020-10-02 14:10:31,441 (64810/MainThread) pgcli.main ERROR - sql: "select * from customer_customeradmin INNER JOIN customer_customeradmin_allowed_groups ON user_id = customeradmin_id WHERE user_id = '4490527';", error: StopIteration()
2020-10-02 14:10:31,463 (64810/MainThread) pgcli.main ERROR - traceback: 'Traceback (most recent call last):\n  File "/usr/local/Cellar/pgcli/3.0.0/libexec/lib/python3.8/site-packages/pgcli/main.py", line 634, in execute_command\n    output, query = self._evaluate_command(text)\n  File "/usr/local/Cellar/pgcli/3.0.0/libexec/lib/python3.8/site-packages/pgcli/main.py", line 909, in _evaluate_command\n    formatted = format_output(title, cur, headers, status, settings)\n  File "/usr/local/Cellar/pgcli/3.0.0/libexec/lib/python3.8/site-packages/pgcli/main.py", line 1432, in format_output\n    first_line = next(formatted)\nStopIteration\n'
2020-10-02 14:10:36,318 (64810/MainThread) pgcli.main ERROR - sql: "select * from customer_customeradmin INNER JOIN customer_customeradmin_allowed_groups ON user_id = customeradmin_id WHERE user_id = '4490527';", error: StopIteration()
2020-10-02 14:10:36,318 (64810/MainThread) pgcli.main ERROR - traceback: 'Traceback (most recent call last):\n  File "/usr/local/Cellar/pgcli/3.0.0/libexec/lib/python3.8/site-packages/pgcli/main.py", line 634, in execute_command\n    output, query = self._evaluate_command(text)\n  File "/usr/local/Cellar/pgcli/3.0.0/libexec/lib/python3.8/site-packages/pgcli/main.py", line 909, in _evaluate_command\n    formatted = format_output(title, cur, headers, status, settings)\n  File "/usr/local/Cellar/pgcli/3.0.0/libexec/lib/python3.8/site-packages/pgcli/main.py", line 1432, in format_output\n    first_line = next(formatted)\nStopIteration\n'
2020-10-02 14:11:09,384 (64810/MainThread) pgcli.main ERROR - sql: "select * from customer_customeradmin_allowed_groups WHERE customeradmin_id = '4490527';", error: StopIteration()
2020-10-02 14:11:09,384 (64810/MainThread) pgcli.main ERROR - traceback: 'Traceback (most recent call last):\n  File "/usr/local/Cellar/pgcli/3.0.0/libexec/lib/python3.8/site-packages/pgcli/main.py", line 634, in execute_command\n    output, query = self._evaluate_command(text)\n  File "/usr/local/Cellar/pgcli/3.0.0/libexec/lib/python3.8/site-packages/pgcli/main.py", line 909, in _evaluate_command\n    formatted = format_output(title, cur, headers, status, settings)\n  File "/usr/local/Cellar/pgcli/3.0.0/libexec/lib/python3.8/site-packages/pgcli/main.py", line 1432, in format_output\n    first_line = next(formatted)\nStopIteration\n'
2020-10-02 14:11:16,143 (64810/MainThread) pgcli.pgexecute ERROR - sql: 'select * from customer_customeradmin_allowed_groups WHERE customeradmin_id = "4490527"', error: UndefinedColumn('column "4490527" does not exist\nLINE 1: ...tomeradmin_allowed_groups WHERE customeradmin_id = "4490527"\n                                                              ^\n')
2020-10-02 14:11:16,143 (64810/MainThread) pgcli.pgexecute ERROR - traceback: 'Traceback (most recent call last):\n  File "/usr/local/Cellar/pgcli/3.0.0/libexec/lib/python3.8/site-packages/pgcli/pgexecute.py", line 409, in run\n    yield self.execute_normal_sql(sql) + (sql, True, False)\n  File "/usr/local/Cellar/pgcli/3.0.0/libexec/lib/python3.8/site-packages/pgcli/pgexecute.py", line 444, in execute_normal_sql\n    cur.execute(split_sql)\npsycopg2.errors.UndefinedColumn: column "4490527" does not exist\nLINE 1: ...tomeradmin_allowed_groups WHERE customeradmin_id = "4490527"\n                                                              ^\n\n'
2020-10-02 14:12:22,135 (64810/MainThread) pgcli.main ERROR - sql: "select * from customer_customeradmin INNER JOIN customer_customeradmin_allowed_groups ON user_id = customeradmin_id WHERE user_id = '4490527';", error: StopIteration()
2020-10-02 14:12:22,136 (64810/MainThread) pgcli.main ERROR - traceback: 'Traceback (most recent call last):\n  File "/usr/local/Cellar/pgcli/3.0.0/libexec/lib/python3.8/site-packages/pgcli/main.py", line 634, in execute_command\n    output, query = self._evaluate_command(text)\n  File "/usr/local/Cellar/pgcli/3.0.0/libexec/lib/python3.8/site-packages/pgcli/main.py", line 909, in _evaluate_command\n    formatted = format_output(title, cur, headers, status, settings)\n  File "/usr/local/Cellar/pgcli/3.0.0/libexec/lib/python3.8/site-packages/pgcli/main.py", line 1432, in format_output\n    first_line = next(formatted)\nStopIteration\n'
2020-10-02 14:15:39,965 (64810/MainThread) pgcli.pgexecute ERROR - sql: 'select * from customer_customeradmin INNER JOIN customer_customer ON customer_customer.id = customer_customeradmin.customer_id', error: QueryCanceled('canceling statement due to user request\n')
2020-10-02 14:15:39,967 (64810/MainThread) pgcli.pgexecute ERROR - traceback: 'Traceback (most recent call last):\n  File "/usr/local/Cellar/pgcli/3.0.0/libexec/lib/python3.8/site-packages/pgcli/pgexecute.py", line 409, in run\n    yield self.execute_normal_sql(sql) + (sql, True, False)\n  File "/usr/local/Cellar/pgcli/3.0.0/libexec/lib/python3.8/site-packages/pgcli/pgexecute.py", line 444, in execute_normal_sql\n    cur.execute(split_sql)\npsycopg2.errors.QueryCanceled: canceling statement due to user request\n\n'
2020-10-02 14:16:35,858 (64810/MainThread) pgcli.main ERROR - sql: "select * from customer_customeradmin INNER JOIN customer_customeradmin_allowed_groups ON customer_customeradmin.user_id = customer_customeradmin_allowed_groups.customeradmin_id WHERE user_id = '4490527';", error: StopIteration()
2020-10-02 14:16:35,858 (64810/MainThread) pgcli.main ERROR - traceback: 'Traceback (most recent call last):\n  File "/usr/local/Cellar/pgcli/3.0.0/libexec/lib/python3.8/site-packages/pgcli/main.py", line 634, in execute_command\n    output, query = self._evaluate_command(text)\n  File "/usr/local/Cellar/pgcli/3.0.0/libexec/lib/python3.8/site-packages/pgcli/main.py", line 909, in _evaluate_command\n    formatted = format_output(title, cur, headers, status, settings)\n  File "/usr/local/Cellar/pgcli/3.0.0/libexec/lib/python3.8/site-packages/pgcli/main.py", line 1432, in format_output\n    first_line = next(formatted)\nStopIteration\n'
2020-10-02 14:17:25,805 (64810/MainThread) pgcli.main ERROR - sql: "select * from customer_customeradmin where user_id = '58668';", error: StopIteration()
2020-10-02 14:17:25,805 (64810/MainThread) pgcli.main ERROR - traceback: 'Traceback (most recent call last):\n  File "/usr/local/Cellar/pgcli/3.0.0/libexec/lib/python3.8/site-packages/pgcli/main.py", line 634, in execute_command\n    output, query = self._evaluate_command(text)\n  File "/usr/local/Cellar/pgcli/3.0.0/libexec/lib/python3.8/site-packages/pgcli/main.py", line 909, in _evaluate_command\n    formatted = format_output(title, cur, headers, status, settings)\n  File "/usr/local/Cellar/pgcli/3.0.0/libexec/lib/python3.8/site-packages/pgcli/main.py", line 1432, in format_output\n    first_line = next(formatted)\nStopIteration\n'
2020-10-02 14:17:34,672 (64810/MainThread) pgcli.pgexecute ERROR - sql: "select * from customer_customeradmin where * = '58668'", error: SyntaxError('syntax error at or near "*"\nLINE 1: select * from customer_customeradmin where * = \'58668\'\n                                                   ^\n')
2020-10-02 14:17:34,672 (64810/MainThread) pgcli.pgexecute ERROR - traceback: 'Traceback (most recent call last):\n  File "/usr/local/Cellar/pgcli/3.0.0/libexec/lib/python3.8/site-packages/pgcli/pgexecute.py", line 409, in run\n    yield self.execute_normal_sql(sql) + (sql, True, False)\n  File "/usr/local/Cellar/pgcli/3.0.0/libexec/lib/python3.8/site-packages/pgcli/pgexecute.py", line 444, in execute_normal_sql\n    cur.execute(split_sql)\npsycopg2.errors.SyntaxError: syntax error at or near "*"\nLINE 1: select * from customer_customeradmin where * = \'58668\'\n                                                   ^\n\n'
2020-10-02 14:17:58,030 (64810/MainThread) pgcli.pgexecute ERROR - sql: "select * from customer_customeradmin INNER JOIN customer_customeradmin_allowed_groups ON customer_customeradmin.user_id = customer_customeradmin_allowed_groups.customeradmin_id WHERE id = '4490527'", error: AmbiguousColumn('column reference "id" is ambiguous\nLINE 1: ...stomeradmin_allowed_groups.customeradmin_id WHERE id = \'4490...\n                                                             ^\n')
2020-10-02 14:17:58,031 (64810/MainThread) pgcli.pgexecute ERROR - traceback: 'Traceback (most recent call last):\n  File "/usr/local/Cellar/pgcli/3.0.0/libexec/lib/python3.8/site-packages/pgcli/pgexecute.py", line 409, in run\n    yield self.execute_normal_sql(sql) + (sql, True, False)\n  File "/usr/local/Cellar/pgcli/3.0.0/libexec/lib/python3.8/site-packages/pgcli/pgexecute.py", line 444, in execute_normal_sql\n    cur.execute(split_sql)\npsycopg2.errors.AmbiguousColumn: column reference "id" is ambiguous\nLINE 1: ...stomeradmin_allowed_groups.customeradmin_id WHERE id = \'4490...\n                                                             ^\n\n'
2020-10-02 14:18:07,339 (64810/MainThread) pgcli.main ERROR - sql: "select * from customer_customeradmin INNER JOIN customer_customeradmin_allowed_groups ON customer_customeradmin.user_id = customer_customeradmin_allowed_groups.customeradmin_id WHERE customer_customeradmin.id = '4490527';", error: StopIteration()
2020-10-02 14:18:07,340 (64810/MainThread) pgcli.main ERROR - traceback: 'Traceback (most recent call last):\n  File "/usr/local/Cellar/pgcli/3.0.0/libexec/lib/python3.8/site-packages/pgcli/main.py", line 634, in execute_command\n    output, query = self._evaluate_command(text)\n  File "/usr/local/Cellar/pgcli/3.0.0/libexec/lib/python3.8/site-packages/pgcli/main.py", line 909, in _evaluate_command\n    formatted = format_output(title, cur, headers, status, settings)\n  File "/usr/local/Cellar/pgcli/3.0.0/libexec/lib/python3.8/site-packages/pgcli/main.py", line 1432, in format_output\n    first_line = next(formatted)\nStopIteration\n'
2020-10-05 11:27:27,198 (23067/MainThread) pgcli.main INFO - Default pager found in PAGER environment variable: "less"
2020-10-05 11:27:27,199 (23067/MainThread) pgcli.main WARNING - import keyring failed: ModuleNotFoundError("No module named 'keyring'").
2020-10-05 11:27:33,958 (23067/MainThread) pgcli.main ERROR - traceback: 'Traceback (most recent call last):\n  File "/usr/local/Cellar/pgcli/3.0.0/libexec/lib/python3.8/site-packages/pgcli/main.py", line 549, in connect\n    pgexecute = PGExecute(database, user, passwd, host, port, dsn, **kwargs)\n  File "/usr/local/Cellar/pgcli/3.0.0/libexec/lib/python3.8/site-packages/pgcli/pgexecute.py", line 214, in __init__\n    self.connect(database, user, password, host, port, dsn, **kwargs)\n  File "/usr/local/Cellar/pgcli/3.0.0/libexec/lib/python3.8/site-packages/pgcli/pgexecute.py", line 254, in connect\n    conn = psycopg2.connect(**conn_params)\n  File "/usr/local/Cellar/pgcli/3.0.0/libexec/lib/python3.8/site-packages/psycopg2/__init__.py", line 127, in connect\n    conn = _connect(dsn, connection_factory=connection_factory, **kwasync)\n  File "/usr/local/Cellar/pgcli/3.0.0/libexec/lib/python3.8/site-packages/pgcli/pgexecute.py", line 39, in _wait_select\n    state = conn.poll()\npsycopg2.OperationalError: FATAL:  password authentication failed for user "sername"\nFATAL:  password authentication failed for user "sername"\n\n\nDuring handling of the above exception, another exception occurred:\n\nTraceback (most recent call last):\n  File "/usr/local/Cellar/pgcli/3.0.0/libexec/lib/python3.8/site-packages/click/termui.py", line 129, in prompt_func\n    return f("")\n  File "/usr/local/Cellar/pgcli/3.0.0/libexec/lib/python3.8/site-packages/click/termui.py", line 54, in hidden_prompt_func\n    return getpass.getpass(prompt)\n  File "/usr/local/opt/python@3.8/Frameworks/Python.framework/Versions/3.8/lib/python3.8/getpass.py", line 77, in unix_getpass\n    passwd = _raw_input(prompt, stream, input=input)\n  File "/usr/local/opt/python@3.8/Frameworks/Python.framework/Versions/3.8/lib/python3.8/getpass.py", line 146, in _raw_input\n    line = input.readline()\nKeyboardInterrupt\n\nDuring handling of the above exception, another exception occurred:\n\nTraceback (most recent call last):\n  File "/usr/local/Cellar/pgcli/3.0.0/libexec/lib/python3.8/site-packages/pgcli/main.py", line 552, in connect\n    passwd = click.prompt(\n  File "/usr/local/Cellar/pgcli/3.0.0/libexec/lib/python3.8/site-packages/click/termui.py", line 147, in prompt\n    value = prompt_func(prompt)\n  File "/usr/local/Cellar/pgcli/3.0.0/libexec/lib/python3.8/site-packages/click/termui.py", line 136, in prompt_func\n    raise Abort()\nclick.exceptions.Abort\n'
2020-10-05 11:27:48,817 (23069/MainThread) pgcli.main INFO - Default pager found in PAGER environment variable: "less"
2020-10-05 11:27:48,818 (23069/MainThread) pgcli.main WARNING - import keyring failed: ModuleNotFoundError("No module named 'keyring'").
2020-10-05 11:36:18,104 (23069/MainThread) pgcli.main ERROR - sql: "select * from user_profile_user inner join customer_customeradmin on user_profile_user.customer_id = customer_customeradmin.customer_id where user_profile_user.customer_id = '600' and user_profile_user.deleted_date = null limit 2;", error: StopIteration()
2020-10-05 11:36:18,108 (23069/MainThread) pgcli.main ERROR - traceback: 'Traceback (most recent call last):\n  File "/usr/local/Cellar/pgcli/3.0.0/libexec/lib/python3.8/site-packages/pgcli/main.py", line 634, in execute_command\n    output, query = self._evaluate_command(text)\n  File "/usr/local/Cellar/pgcli/3.0.0/libexec/lib/python3.8/site-packages/pgcli/main.py", line 909, in _evaluate_command\n    formatted = format_output(title, cur, headers, status, settings)\n  File "/usr/local/Cellar/pgcli/3.0.0/libexec/lib/python3.8/site-packages/pgcli/main.py", line 1432, in format_output\n    first_line = next(formatted)\nStopIteration\n'
2020-10-05 11:39:11,053 (23069/MainThread) pgcli.pgexecute ERROR - sql: "select id, email from user_profile_user inner join customer_customeradmin on user_profile_user.customer_id = customer_customeradmin.customer_id where user_profile_user.customer_id = '600' and user_profile_user.deleted_date is null limit 2", error: AmbiguousColumn('column reference "id" is ambiguous\nLINE 1: select id, email from user_profile_user inner join customer_...\n               ^\n')
2020-10-05 11:39:11,056 (23069/MainThread) pgcli.pgexecute ERROR - traceback: 'Traceback (most recent call last):\n  File "/usr/local/Cellar/pgcli/3.0.0/libexec/lib/python3.8/site-packages/pgcli/pgexecute.py", line 409, in run\n    yield self.execute_normal_sql(sql) + (sql, True, False)\n  File "/usr/local/Cellar/pgcli/3.0.0/libexec/lib/python3.8/site-packages/pgcli/pgexecute.py", line 444, in execute_normal_sql\n    cur.execute(split_sql)\npsycopg2.errors.AmbiguousColumn: column reference "id" is ambiguous\nLINE 1: select id, email from user_profile_user inner join customer_...\n               ^\n\n'
2020-10-05 11:39:20,816 (23069/MainThread) pgcli.pgexecute ERROR - sql: "select id email from user_profile_user inner join customer_customeradmin on user_profile_user.customer_id = customer_customeradmin.customer_id where user_profile_user.customer_id = '600' and user_profile_user.deleted_date is null limit 2", error: AmbiguousColumn('column reference "id" is ambiguous\nLINE 1: select id email from user_profile_user inner join customer_c...\n               ^\n')
2020-10-05 11:39:20,817 (23069/MainThread) pgcli.pgexecute ERROR - traceback: 'Traceback (most recent call last):\n  File "/usr/local/Cellar/pgcli/3.0.0/libexec/lib/python3.8/site-packages/pgcli/pgexecute.py", line 409, in run\n    yield self.execute_normal_sql(sql) + (sql, True, False)\n  File "/usr/local/Cellar/pgcli/3.0.0/libexec/lib/python3.8/site-packages/pgcli/pgexecute.py", line 444, in execute_normal_sql\n    cur.execute(split_sql)\npsycopg2.errors.AmbiguousColumn: column reference "id" is ambiguous\nLINE 1: select id email from user_profile_user inner join customer_c...\n               ^\n\n'
2020-10-05 11:39:24,943 (23069/MainThread) pgcli.pgexecute ERROR - sql: "select id, email from user_profile_user inner join customer_customeradmin on user_profile_user.customer_id = customer_customeradmin.customer_id where user_profile_user.customer_id = '600' and user_profile_user.deleted_date is null limit 2", error: AmbiguousColumn('column reference "id" is ambiguous\nLINE 1: select id, email from user_profile_user inner join customer_...\n               ^\n')
2020-10-05 11:39:24,943 (23069/MainThread) pgcli.pgexecute ERROR - traceback: 'Traceback (most recent call last):\n  File "/usr/local/Cellar/pgcli/3.0.0/libexec/lib/python3.8/site-packages/pgcli/pgexecute.py", line 409, in run\n    yield self.execute_normal_sql(sql) + (sql, True, False)\n  File "/usr/local/Cellar/pgcli/3.0.0/libexec/lib/python3.8/site-packages/pgcli/pgexecute.py", line 444, in execute_normal_sql\n    cur.execute(split_sql)\npsycopg2.errors.AmbiguousColumn: column reference "id" is ambiguous\nLINE 1: select id, email from user_profile_user inner join customer_...\n               ^\n\n'
2020-10-05 11:41:13,184 (23069/MainThread) pgcli.pgexecute ERROR - sql: "with t as (select id, email from user_profile_user inner join customer_customeradmin on user_profile_user.customer_id = customer_customeradmin.customer_id where user_profile_user.customer_id = '600' and user_profile_user.deleted_date is null limit 2)", error: SyntaxError("syntax error at end of input\nLINE 1: ... = '600' and user_profile_user.deleted_date is null limit 2)\n                                                                       ^\n")
2020-10-05 11:41:13,186 (23069/MainThread) pgcli.pgexecute ERROR - traceback: 'Traceback (most recent call last):\n  File "/usr/local/Cellar/pgcli/3.0.0/libexec/lib/python3.8/site-packages/pgcli/pgexecute.py", line 409, in run\n    yield self.execute_normal_sql(sql) + (sql, True, False)\n  File "/usr/local/Cellar/pgcli/3.0.0/libexec/lib/python3.8/site-packages/pgcli/pgexecute.py", line 444, in execute_normal_sql\n    cur.execute(split_sql)\npsycopg2.errors.SyntaxError: syntax error at end of input\nLINE 1: ... = \'600\' and user_profile_user.deleted_date is null limit 2)\n                                                                       ^\n\n'
2020-10-05 11:41:25,202 (23069/MainThread) pgcli.pgexecute ERROR - sql: "with t as (select id, email from user_profile_user inner join customer_customeradmin on user_profile_user.customer_id = customer_customeradmin.customer_id where user_profile_user.customer_id = '600' and user_profile_user.deleted_date is null limit 2) select json_agg(t) from t", error: AmbiguousColumn('column reference "id" is ambiguous\nLINE 1: with t as (select id, email from user_profile_user inner joi...\n                          ^\n')
2020-10-05 11:41:25,203 (23069/MainThread) pgcli.pgexecute ERROR - traceback: 'Traceback (most recent call last):\n  File "/usr/local/Cellar/pgcli/3.0.0/libexec/lib/python3.8/site-packages/pgcli/pgexecute.py", line 409, in run\n    yield self.execute_normal_sql(sql) + (sql, True, False)\n  File "/usr/local/Cellar/pgcli/3.0.0/libexec/lib/python3.8/site-packages/pgcli/pgexecute.py", line 444, in execute_normal_sql\n    cur.execute(split_sql)\npsycopg2.errors.AmbiguousColumn: column reference "id" is ambiguous\nLINE 1: with t as (select id, email from user_profile_user inner joi...\n                          ^\n\n'
2020-10-05 11:41:49,653 (23069/MainThread) pgcli.pgexecute ERROR - sql: "with t as (select email, pk from user_profile_user inner join customer_customeradmin on user_profile_user.customer_id = customer_customeradmin.customer_id where user_profile_user.customer_id = '600' and user_profile_user.deleted_date is null limit 2) select json_agg(t) from t", error: UndefinedColumn('column "pk" does not exist\nLINE 1: with t as (select email, pk from user_profile_user inner joi...\n                                 ^\n')
2020-10-05 11:41:49,654 (23069/MainThread) pgcli.pgexecute ERROR - traceback: 'Traceback (most recent call last):\n  File "/usr/local/Cellar/pgcli/3.0.0/libexec/lib/python3.8/site-packages/pgcli/pgexecute.py", line 409, in run\n    yield self.execute_normal_sql(sql) + (sql, True, False)\n  File "/usr/local/Cellar/pgcli/3.0.0/libexec/lib/python3.8/site-packages/pgcli/pgexecute.py", line 444, in execute_normal_sql\n    cur.execute(split_sql)\npsycopg2.errors.UndefinedColumn: column "pk" does not exist\nLINE 1: with t as (select email, pk from user_profile_user inner joi...\n                                 ^\n\n'
2020-10-05 11:46:16,071 (23069/MainThread) pgcli.main ERROR - sql: "select * from customer_customeradmin where user_id = '4326324';", error: StopIteration()
2020-10-05 11:46:16,072 (23069/MainThread) pgcli.main ERROR - traceback: 'Traceback (most recent call last):\n  File "/usr/local/Cellar/pgcli/3.0.0/libexec/lib/python3.8/site-packages/pgcli/main.py", line 634, in execute_command\n    output, query = self._evaluate_command(text)\n  File "/usr/local/Cellar/pgcli/3.0.0/libexec/lib/python3.8/site-packages/pgcli/main.py", line 909, in _evaluate_command\n    formatted = format_output(title, cur, headers, status, settings)\n  File "/usr/local/Cellar/pgcli/3.0.0/libexec/lib/python3.8/site-packages/pgcli/main.py", line 1432, in format_output\n    first_line = next(formatted)\nStopIteration\n'
2020-10-05 14:33:56,572 (36572/MainThread) pgcli.main INFO - Default pager found in PAGER environment variable: "less"
2020-10-05 14:33:56,572 (36572/MainThread) pgcli.main WARNING - import keyring failed: ModuleNotFoundError("No module named 'keyring'").
2020-10-05 14:34:41,103 (36572/MainThread) pgcli.pgexecute ERROR - sql: '\\x\\x', error: SyntaxError('syntax error at or near "\\"\nLINE 1: \\x\\x\n        ^\n')
2020-10-05 14:34:41,106 (36572/MainThread) pgcli.pgexecute ERROR - traceback: 'Traceback (most recent call last):\n  File "/usr/local/Cellar/pgcli/3.0.0/libexec/lib/python3.8/site-packages/pgcli/pgexecute.py", line 409, in run\n    yield self.execute_normal_sql(sql) + (sql, True, False)\n  File "/usr/local/Cellar/pgcli/3.0.0/libexec/lib/python3.8/site-packages/pgcli/pgexecute.py", line 444, in execute_normal_sql\n    cur.execute(split_sql)\npsycopg2.errors.SyntaxError: syntax error at or near "\\"\nLINE 1: \\x\\x\n        ^\n\n'
2020-10-07 23:08:00,933 (28585/MainThread) pgcli.main INFO - Default pager found in PAGER environment variable: "less"
2020-10-07 23:08:00,934 (28585/MainThread) pgcli.main WARNING - import keyring failed: ModuleNotFoundError("No module named 'keyring'").
2020-10-07 23:08:00,968 (28585/MainThread) pgcli.main ERROR - traceback: 'Traceback (most recent call last):\n  File "/usr/local/Cellar/pgcli/3.0.0/libexec/lib/python3.8/site-packages/pgcli/main.py", line 562, in connect\n    raise e\n  File "/usr/local/Cellar/pgcli/3.0.0/libexec/lib/python3.8/site-packages/pgcli/main.py", line 549, in connect\n    pgexecute = PGExecute(database, user, passwd, host, port, dsn, **kwargs)\n  File "/usr/local/Cellar/pgcli/3.0.0/libexec/lib/python3.8/site-packages/pgcli/pgexecute.py", line 214, in __init__\n    self.connect(database, user, password, host, port, dsn, **kwargs)\n  File "/usr/local/Cellar/pgcli/3.0.0/libexec/lib/python3.8/site-packages/pgcli/pgexecute.py", line 254, in connect\n    conn = psycopg2.connect(**conn_params)\n  File "/usr/local/Cellar/pgcli/3.0.0/libexec/lib/python3.8/site-packages/psycopg2/__init__.py", line 127, in connect\n    conn = _connect(dsn, connection_factory=connection_factory, **kwasync)\n  File "/usr/local/Cellar/pgcli/3.0.0/libexec/lib/python3.8/site-packages/pgcli/pgexecute.py", line 39, in _wait_select\n    state = conn.poll()\npsycopg2.OperationalError: could not connect to server: Connection refused\n\tIs the server running on host "localhost" (::1) and accepting\n\tTCP/IP connections on port 5432?\ncould not connect to server: Connection refused\n\tIs the server running on host "localhost" (127.0.0.1) and accepting\n\tTCP/IP connections on port 5432?\n\n'
2020-10-07 23:08:22,073 (28587/MainThread) pgcli.main INFO - Default pager found in PAGER environment variable: "less"
2020-10-07 23:08:22,074 (28587/MainThread) pgcli.main WARNING - import keyring failed: ModuleNotFoundError("No module named 'keyring'").
2020-10-07 23:08:43,480 (28608/MainThread) pgcli.main INFO - Default pager found in PAGER environment variable: "less"
2020-10-07 23:08:43,480 (28608/MainThread) pgcli.main WARNING - import keyring failed: ModuleNotFoundError("No module named 'keyring'").
2020-10-07 23:08:45,593 (28608/MainThread) pgcli.main ERROR - traceback: 'Traceback (most recent call last):\n  File "/usr/local/Cellar/pgcli/3.0.0/libexec/lib/python3.8/site-packages/pgcli/main.py", line 562, in connect\n    raise e\n  File "/usr/local/Cellar/pgcli/3.0.0/libexec/lib/python3.8/site-packages/pgcli/main.py", line 549, in connect\n    pgexecute = PGExecute(database, user, passwd, host, port, dsn, **kwargs)\n  File "/usr/local/Cellar/pgcli/3.0.0/libexec/lib/python3.8/site-packages/pgcli/pgexecute.py", line 214, in __init__\n    self.connect(database, user, password, host, port, dsn, **kwargs)\n  File "/usr/local/Cellar/pgcli/3.0.0/libexec/lib/python3.8/site-packages/pgcli/pgexecute.py", line 254, in connect\n    conn = psycopg2.connect(**conn_params)\n  File "/usr/local/Cellar/pgcli/3.0.0/libexec/lib/python3.8/site-packages/psycopg2/__init__.py", line 127, in connect\n    conn = _connect(dsn, connection_factory=connection_factory, **kwasync)\n  File "/usr/local/Cellar/pgcli/3.0.0/libexec/lib/python3.8/site-packages/pgcli/pgexecute.py", line 39, in _wait_select\n    state = conn.poll()\npsycopg2.OperationalError: could not connect to server: Connection refused\n\tIs the server running on host "localhost" (::1) and accepting\n\tTCP/IP connections on port 5432?\ncould not connect to server: Connection refused\n\tIs the server running on host "localhost" (127.0.0.1) and accepting\n\tTCP/IP connections on port 5432?\n\n'
2020-10-07 23:09:15,577 (28615/MainThread) pgcli.main INFO - Default pager found in PAGER environment variable: "less"
2020-10-07 23:09:15,577 (28615/MainThread) pgcli.main WARNING - import keyring failed: ModuleNotFoundError("No module named 'keyring'").
2020-10-07 23:09:17,612 (28615/MainThread) pgcli.main ERROR - traceback: 'Traceback (most recent call last):\n  File "/usr/local/Cellar/pgcli/3.0.0/libexec/lib/python3.8/site-packages/pgcli/main.py", line 562, in connect\n    raise e\n  File "/usr/local/Cellar/pgcli/3.0.0/libexec/lib/python3.8/site-packages/pgcli/main.py", line 549, in connect\n    pgexecute = PGExecute(database, user, passwd, host, port, dsn, **kwargs)\n  File "/usr/local/Cellar/pgcli/3.0.0/libexec/lib/python3.8/site-packages/pgcli/pgexecute.py", line 214, in __init__\n    self.connect(database, user, password, host, port, dsn, **kwargs)\n  File "/usr/local/Cellar/pgcli/3.0.0/libexec/lib/python3.8/site-packages/pgcli/pgexecute.py", line 254, in connect\n    conn = psycopg2.connect(**conn_params)\n  File "/usr/local/Cellar/pgcli/3.0.0/libexec/lib/python3.8/site-packages/psycopg2/__init__.py", line 127, in connect\n    conn = _connect(dsn, connection_factory=connection_factory, **kwasync)\n  File "/usr/local/Cellar/pgcli/3.0.0/libexec/lib/python3.8/site-packages/pgcli/pgexecute.py", line 39, in _wait_select\n    state = conn.poll()\npsycopg2.OperationalError: could not connect to server: Connection refused\n\tIs the server running on host "127.0.0.1" and accepting\n\tTCP/IP connections on port 5432?\n\n'
2020-10-07 23:09:42,390 (28622/MainThread) pgcli.main INFO - Default pager found in PAGER environment variable: "less"
2020-10-07 23:09:42,390 (28622/MainThread) pgcli.main WARNING - import keyring failed: ModuleNotFoundError("No module named 'keyring'").
2020-10-07 23:09:44,360 (28622/MainThread) pgcli.main ERROR - traceback: 'Traceback (most recent call last):\n  File "/usr/local/Cellar/pgcli/3.0.0/libexec/lib/python3.8/site-packages/pgcli/main.py", line 562, in connect\n    raise e\n  File "/usr/local/Cellar/pgcli/3.0.0/libexec/lib/python3.8/site-packages/pgcli/main.py", line 549, in connect\n    pgexecute = PGExecute(database, user, passwd, host, port, dsn, **kwargs)\n  File "/usr/local/Cellar/pgcli/3.0.0/libexec/lib/python3.8/site-packages/pgcli/pgexecute.py", line 214, in __init__\n    self.connect(database, user, password, host, port, dsn, **kwargs)\n  File "/usr/local/Cellar/pgcli/3.0.0/libexec/lib/python3.8/site-packages/pgcli/pgexecute.py", line 254, in connect\n    conn = psycopg2.connect(**conn_params)\n  File "/usr/local/Cellar/pgcli/3.0.0/libexec/lib/python3.8/site-packages/psycopg2/__init__.py", line 127, in connect\n    conn = _connect(dsn, connection_factory=connection_factory, **kwasync)\n  File "/usr/local/Cellar/pgcli/3.0.0/libexec/lib/python3.8/site-packages/pgcli/pgexecute.py", line 39, in _wait_select\n    state = conn.poll()\npsycopg2.OperationalError: could not connect to server: Connection refused\n\tIs the server running on host "127.0.0.1" and accepting\n\tTCP/IP connections on port 5432?\n\n'
2020-10-07 23:10:18,401 (28635/MainThread) pgcli.main INFO - Default pager found in PAGER environment variable: "less"
2020-10-07 23:10:18,402 (28635/MainThread) pgcli.main WARNING - import keyring failed: ModuleNotFoundError("No module named 'keyring'").
2020-10-07 23:10:20,461 (28635/MainThread) pgcli.main ERROR - traceback: 'Traceback (most recent call last):\n  File "/usr/local/Cellar/pgcli/3.0.0/libexec/lib/python3.8/site-packages/pgcli/main.py", line 562, in connect\n    raise e\n  File "/usr/local/Cellar/pgcli/3.0.0/libexec/lib/python3.8/site-packages/pgcli/main.py", line 549, in connect\n    pgexecute = PGExecute(database, user, passwd, host, port, dsn, **kwargs)\n  File "/usr/local/Cellar/pgcli/3.0.0/libexec/lib/python3.8/site-packages/pgcli/pgexecute.py", line 214, in __init__\n    self.connect(database, user, password, host, port, dsn, **kwargs)\n  File "/usr/local/Cellar/pgcli/3.0.0/libexec/lib/python3.8/site-packages/pgcli/pgexecute.py", line 254, in connect\n    conn = psycopg2.connect(**conn_params)\n  File "/usr/local/Cellar/pgcli/3.0.0/libexec/lib/python3.8/site-packages/psycopg2/__init__.py", line 127, in connect\n    conn = _connect(dsn, connection_factory=connection_factory, **kwasync)\n  File "/usr/local/Cellar/pgcli/3.0.0/libexec/lib/python3.8/site-packages/pgcli/pgexecute.py", line 39, in _wait_select\n    state = conn.poll()\npsycopg2.OperationalError: could not connect to server: Connection refused\n\tIs the server running on host "localhost" (::1) and accepting\n\tTCP/IP connections on port 5432?\ncould not connect to server: Connection refused\n\tIs the server running on host "localhost" (127.0.0.1) and accepting\n\tTCP/IP connections on port 5432?\n\n'
2020-10-07 23:11:37,402 (28669/MainThread) pgcli.main INFO - Default pager found in PAGER environment variable: "less"
2020-10-07 23:11:37,403 (28669/MainThread) pgcli.main WARNING - import keyring failed: ModuleNotFoundError("No module named 'keyring'").
2020-10-07 23:11:40,122 (28669/MainThread) pgcli.main ERROR - traceback: 'Traceback (most recent call last):\n  File "/usr/local/Cellar/pgcli/3.0.0/libexec/lib/python3.8/site-packages/pgcli/main.py", line 562, in connect\n    raise e\n  File "/usr/local/Cellar/pgcli/3.0.0/libexec/lib/python3.8/site-packages/pgcli/main.py", line 549, in connect\n    pgexecute = PGExecute(database, user, passwd, host, port, dsn, **kwargs)\n  File "/usr/local/Cellar/pgcli/3.0.0/libexec/lib/python3.8/site-packages/pgcli/pgexecute.py", line 214, in __init__\n    self.connect(database, user, password, host, port, dsn, **kwargs)\n  File "/usr/local/Cellar/pgcli/3.0.0/libexec/lib/python3.8/site-packages/pgcli/pgexecute.py", line 254, in connect\n    conn = psycopg2.connect(**conn_params)\n  File "/usr/local/Cellar/pgcli/3.0.0/libexec/lib/python3.8/site-packages/psycopg2/__init__.py", line 127, in connect\n    conn = _connect(dsn, connection_factory=connection_factory, **kwasync)\n  File "/usr/local/Cellar/pgcli/3.0.0/libexec/lib/python3.8/site-packages/pgcli/pgexecute.py", line 39, in _wait_select\n    state = conn.poll()\npsycopg2.OperationalError: could not connect to server: Connection refused\n\tIs the server running on host "localhost" (::1) and accepting\n\tTCP/IP connections on port 5432?\ncould not connect to server: Connection refused\n\tIs the server running on host "localhost" (127.0.0.1) and accepting\n\tTCP/IP connections on port 5432?\n\n'
2020-10-07 23:13:31,283 (28714/MainThread) pgcli.main INFO - Default pager found in PAGER environment variable: "less"
2020-10-07 23:13:31,283 (28714/MainThread) pgcli.main WARNING - import keyring failed: ModuleNotFoundError("No module named 'keyring'").
2020-10-07 23:13:31,289 (28714/MainThread) pgcli.main ERROR - traceback: 'Traceback (most recent call last):\n  File "/usr/local/Cellar/pgcli/3.0.0/libexec/lib/python3.8/site-packages/pgcli/main.py", line 562, in connect\n    raise e\n  File "/usr/local/Cellar/pgcli/3.0.0/libexec/lib/python3.8/site-packages/pgcli/main.py", line 549, in connect\n    pgexecute = PGExecute(database, user, passwd, host, port, dsn, **kwargs)\n  File "/usr/local/Cellar/pgcli/3.0.0/libexec/lib/python3.8/site-packages/pgcli/pgexecute.py", line 214, in __init__\n    self.connect(database, user, password, host, port, dsn, **kwargs)\n  File "/usr/local/Cellar/pgcli/3.0.0/libexec/lib/python3.8/site-packages/pgcli/pgexecute.py", line 254, in connect\n    conn = psycopg2.connect(**conn_params)\n  File "/usr/local/Cellar/pgcli/3.0.0/libexec/lib/python3.8/site-packages/psycopg2/__init__.py", line 127, in connect\n    conn = _connect(dsn, connection_factory=connection_factory, **kwasync)\npsycopg2.OperationalError: could not connect to server: No such file or directory\n\tIs the server running locally and accepting\n\tconnections on Unix domain socket "/tmp/.s.PGSQL.5432"?\n\n'
2020-10-07 23:13:43,207 (28716/MainThread) pgcli.main INFO - Default pager found in PAGER environment variable: "less"
2020-10-07 23:13:43,207 (28716/MainThread) pgcli.main WARNING - import keyring failed: ModuleNotFoundError("No module named 'keyring'").
2020-10-07 23:13:43,214 (28716/MainThread) pgcli.main ERROR - traceback: 'Traceback (most recent call last):\n  File "/usr/local/Cellar/pgcli/3.0.0/libexec/lib/python3.8/site-packages/pgcli/main.py", line 562, in connect\n    raise e\n  File "/usr/local/Cellar/pgcli/3.0.0/libexec/lib/python3.8/site-packages/pgcli/main.py", line 549, in connect\n    pgexecute = PGExecute(database, user, passwd, host, port, dsn, **kwargs)\n  File "/usr/local/Cellar/pgcli/3.0.0/libexec/lib/python3.8/site-packages/pgcli/pgexecute.py", line 214, in __init__\n    self.connect(database, user, password, host, port, dsn, **kwargs)\n  File "/usr/local/Cellar/pgcli/3.0.0/libexec/lib/python3.8/site-packages/pgcli/pgexecute.py", line 254, in connect\n    conn = psycopg2.connect(**conn_params)\n  File "/usr/local/Cellar/pgcli/3.0.0/libexec/lib/python3.8/site-packages/psycopg2/__init__.py", line 127, in connect\n    conn = _connect(dsn, connection_factory=connection_factory, **kwasync)\n  File "/usr/local/Cellar/pgcli/3.0.0/libexec/lib/python3.8/site-packages/pgcli/pgexecute.py", line 39, in _wait_select\n    state = conn.poll()\npsycopg2.OperationalError: could not connect to server: Connection refused\n\tIs the server running on host "localhost" (::1) and accepting\n\tTCP/IP connections on port 5432?\ncould not connect to server: Connection refused\n\tIs the server running on host "localhost" (127.0.0.1) and accepting\n\tTCP/IP connections on port 5432?\n\n'
2020-10-07 23:14:12,689 (28723/MainThread) pgcli.main INFO - Default pager found in PAGER environment variable: "less"
2020-10-07 23:14:12,691 (28723/MainThread) pgcli.main WARNING - import keyring failed: ModuleNotFoundError("No module named 'keyring'").
2020-10-07 23:15:13,618 (28723/MainThread) pgcli.main ERROR - traceback: 'Traceback (most recent call last):\n  File "/usr/local/Cellar/pgcli/3.0.0/libexec/lib/python3.8/site-packages/pgcli/pgexecute.py", line 43, in _wait_select\n    select.select([conn.fileno()], [], [], _WAIT_SELECT_TIMEOUT)\nKeyboardInterrupt\n\nDuring handling of the above exception, another exception occurred:\n\nTraceback (most recent call last):\n  File "/usr/local/Cellar/pgcli/3.0.0/libexec/lib/python3.8/site-packages/pgcli/main.py", line 562, in connect\n    raise e\n  File "/usr/local/Cellar/pgcli/3.0.0/libexec/lib/python3.8/site-packages/pgcli/main.py", line 549, in connect\n    pgexecute = PGExecute(database, user, passwd, host, port, dsn, **kwargs)\n  File "/usr/local/Cellar/pgcli/3.0.0/libexec/lib/python3.8/site-packages/pgcli/pgexecute.py", line 214, in __init__\n    self.connect(database, user, password, host, port, dsn, **kwargs)\n  File "/usr/local/Cellar/pgcli/3.0.0/libexec/lib/python3.8/site-packages/pgcli/pgexecute.py", line 254, in connect\n    conn = psycopg2.connect(**conn_params)\n  File "/usr/local/Cellar/pgcli/3.0.0/libexec/lib/python3.8/site-packages/psycopg2/__init__.py", line 127, in connect\n    conn = _connect(dsn, connection_factory=connection_factory, **kwasync)\n  File "/usr/local/Cellar/pgcli/3.0.0/libexec/lib/python3.8/site-packages/pgcli/pgexecute.py", line 49, in _wait_select\n    conn.cancel()\npsycopg2.OperationalError: asynchronous connection attempt underway\n'
2020-10-07 23:16:10,381 (28878/MainThread) pgcli.main INFO - Default pager found in PAGER environment variable: "less"
2020-10-07 23:16:10,382 (28878/MainThread) pgcli.main WARNING - import keyring failed: ModuleNotFoundError("No module named 'keyring'").
2020-10-07 23:16:31,053 (28878/MainThread) pgcli.pgexecute ERROR - sql: 'select * from user_user', error: UndefinedTable('relation "user_user" does not exist\nLINE 1: select * from user_user\n                      ^\n')
2020-10-07 23:16:31,055 (28878/MainThread) pgcli.pgexecute ERROR - traceback: 'Traceback (most recent call last):\n  File "/usr/local/Cellar/pgcli/3.0.0/libexec/lib/python3.8/site-packages/pgcli/pgexecute.py", line 409, in run\n    yield self.execute_normal_sql(sql) + (sql, True, False)\n  File "/usr/local/Cellar/pgcli/3.0.0/libexec/lib/python3.8/site-packages/pgcli/pgexecute.py", line 444, in execute_normal_sql\n    cur.execute(split_sql)\npsycopg2.errors.UndefinedTable: relation "user_user" does not exist\nLINE 1: select * from user_user\n                      ^\n\n'
2020-10-13 15:58:45,835 (49537/MainThread) pgcli.main INFO - Default pager found in PAGER environment variable: "less"
2020-10-13 15:58:45,836 (49537/MainThread) pgcli.main WARNING - import keyring failed: ModuleNotFoundError("No module named 'keyring'").
2020-10-13 16:23:48,573 (49537/MainThread) pgcli.pgexecute ERROR - sql: 'select * from auth_client_permissions ORDER BY random() LIMIT 1', error: UndefinedTable('relation "auth_client_permissions" does not exist\nLINE 1: select * from auth_client_permissions ORDER BY random() LIMI...\n                      ^\n')
2020-10-13 16:23:48,588 (49537/MainThread) pgcli.pgexecute ERROR - traceback: 'Traceback (most recent call last):\n  File "/usr/local/Cellar/pgcli/3.0.0/libexec/lib/python3.8/site-packages/pgcli/pgexecute.py", line 409, in run\n    yield self.execute_normal_sql(sql) + (sql, True, False)\n  File "/usr/local/Cellar/pgcli/3.0.0/libexec/lib/python3.8/site-packages/pgcli/pgexecute.py", line 444, in execute_normal_sql\n    cur.execute(split_sql)\npsycopg2.errors.UndefinedTable: relation "auth_client_permissions" does not exist\nLINE 1: select * from auth_client_permissions ORDER BY random() LIMI...\n                      ^\n\n'
2020-10-13 16:25:02,809 (49537/MainThread) pgcli.main ERROR - sql: "select * from customer_customeradmin_allowed_groups WHERE customeradmin_id = '4493537';", error: StopIteration()
2020-10-13 16:25:02,819 (49537/MainThread) pgcli.main ERROR - traceback: 'Traceback (most recent call last):\n  File "/usr/local/Cellar/pgcli/3.0.0/libexec/lib/python3.8/site-packages/pgcli/main.py", line 634, in execute_command\n    output, query = self._evaluate_command(text)\n  File "/usr/local/Cellar/pgcli/3.0.0/libexec/lib/python3.8/site-packages/pgcli/main.py", line 909, in _evaluate_command\n    formatted = format_output(title, cur, headers, status, settings)\n  File "/usr/local/Cellar/pgcli/3.0.0/libexec/lib/python3.8/site-packages/pgcli/main.py", line 1432, in format_output\n    first_line = next(formatted)\nStopIteration\n'
2020-10-13 16:29:40,317 (49537/MainThread) pgcli.main ERROR - sql: "select * from customer_customeradmin_allowed_groups WHERE id = '59437';", error: StopIteration()
2020-10-13 16:29:40,318 (49537/MainThread) pgcli.main ERROR - traceback: 'Traceback (most recent call last):\n  File "/usr/local/Cellar/pgcli/3.0.0/libexec/lib/python3.8/site-packages/pgcli/main.py", line 634, in execute_command\n    output, query = self._evaluate_command(text)\n  File "/usr/local/Cellar/pgcli/3.0.0/libexec/lib/python3.8/site-packages/pgcli/main.py", line 909, in _evaluate_command\n    formatted = format_output(title, cur, headers, status, settings)\n  File "/usr/local/Cellar/pgcli/3.0.0/libexec/lib/python3.8/site-packages/pgcli/main.py", line 1432, in format_output\n    first_line = next(formatted)\nStopIteration\n'
2020-10-13 16:29:56,187 (49537/MainThread) pgcli.main ERROR - sql: "select * from customer_customeradmin_allowed_groups WHERE customeradmin_id = '4493547';", error: StopIteration()
2020-10-13 16:29:56,187 (49537/MainThread) pgcli.main ERROR - traceback: 'Traceback (most recent call last):\n  File "/usr/local/Cellar/pgcli/3.0.0/libexec/lib/python3.8/site-packages/pgcli/main.py", line 634, in execute_command\n    output, query = self._evaluate_command(text)\n  File "/usr/local/Cellar/pgcli/3.0.0/libexec/lib/python3.8/site-packages/pgcli/main.py", line 909, in _evaluate_command\n    formatted = format_output(title, cur, headers, status, settings)\n  File "/usr/local/Cellar/pgcli/3.0.0/libexec/lib/python3.8/site-packages/pgcli/main.py", line 1432, in format_output\n    first_line = next(formatted)\nStopIteration\n'
2020-10-13 16:32:11,667 (49537/MainThread) pgcli.main ERROR - sql: 'select * from user_profile_user_groups ORDER BY random() LIMIT 1;', error: StopIteration()
2020-10-13 16:32:11,667 (49537/MainThread) pgcli.main ERROR - traceback: 'Traceback (most recent call last):\n  File "/usr/local/Cellar/pgcli/3.0.0/libexec/lib/python3.8/site-packages/pgcli/main.py", line 634, in execute_command\n    output, query = self._evaluate_command(text)\n  File "/usr/local/Cellar/pgcli/3.0.0/libexec/lib/python3.8/site-packages/pgcli/main.py", line 909, in _evaluate_command\n    formatted = format_output(title, cur, headers, status, settings)\n  File "/usr/local/Cellar/pgcli/3.0.0/libexec/lib/python3.8/site-packages/pgcli/main.py", line 1432, in format_output\n    first_line = next(formatted)\nStopIteration\n'
2020-10-13 16:32:52,649 (49537/MainThread) pgcli.main ERROR - sql: "select * from auth_group_permissions WHERE id = '59437';", error: StopIteration()
2020-10-13 16:32:52,649 (49537/MainThread) pgcli.main ERROR - traceback: 'Traceback (most recent call last):\n  File "/usr/local/Cellar/pgcli/3.0.0/libexec/lib/python3.8/site-packages/pgcli/main.py", line 634, in execute_command\n    output, query = self._evaluate_command(text)\n  File "/usr/local/Cellar/pgcli/3.0.0/libexec/lib/python3.8/site-packages/pgcli/main.py", line 909, in _evaluate_command\n    formatted = format_output(title, cur, headers, status, settings)\n  File "/usr/local/Cellar/pgcli/3.0.0/libexec/lib/python3.8/site-packages/pgcli/main.py", line 1432, in format_output\n    first_line = next(formatted)\nStopIteration\n'
2020-10-13 16:39:02,577 (49537/MainThread) pgcli.main ERROR - sql: 'select * from user_profile_user_user_permissions ORDER BY random() LIMIT 1;', error: StopIteration()
2020-10-13 16:39:02,578 (49537/MainThread) pgcli.main ERROR - traceback: 'Traceback (most recent call last):\n  File "/usr/local/Cellar/pgcli/3.0.0/libexec/lib/python3.8/site-packages/pgcli/main.py", line 634, in execute_command\n    output, query = self._evaluate_command(text)\n  File "/usr/local/Cellar/pgcli/3.0.0/libexec/lib/python3.8/site-packages/pgcli/main.py", line 909, in _evaluate_command\n    formatted = format_output(title, cur, headers, status, settings)\n  File "/usr/local/Cellar/pgcli/3.0.0/libexec/lib/python3.8/site-packages/pgcli/main.py", line 1432, in format_output\n    first_line = next(formatted)\nStopIteration\n'
2020-10-13 16:39:20,952 (49537/MainThread) pgcli.main ERROR - sql: 'select * from user_profile_user_groups ORDER BY random() LIMIT 1;', error: StopIteration()
2020-10-13 16:39:20,953 (49537/MainThread) pgcli.main ERROR - traceback: 'Traceback (most recent call last):\n  File "/usr/local/Cellar/pgcli/3.0.0/libexec/lib/python3.8/site-packages/pgcli/main.py", line 634, in execute_command\n    output, query = self._evaluate_command(text)\n  File "/usr/local/Cellar/pgcli/3.0.0/libexec/lib/python3.8/site-packages/pgcli/main.py", line 909, in _evaluate_command\n    formatted = format_output(title, cur, headers, status, settings)\n  File "/usr/local/Cellar/pgcli/3.0.0/libexec/lib/python3.8/site-packages/pgcli/main.py", line 1432, in format_output\n    first_line = next(formatted)\nStopIteration\n'
2020-10-13 16:45:42,424 (49537/MainThread) pgcli.main ERROR - sql: 'select * from notify_notification_groups WHERE group_id = 176925;', error: StopIteration()
2020-10-13 16:45:42,424 (49537/MainThread) pgcli.main ERROR - traceback: 'Traceback (most recent call last):\n  File "/usr/local/Cellar/pgcli/3.0.0/libexec/lib/python3.8/site-packages/pgcli/main.py", line 634, in execute_command\n    output, query = self._evaluate_command(text)\n  File "/usr/local/Cellar/pgcli/3.0.0/libexec/lib/python3.8/site-packages/pgcli/main.py", line 909, in _evaluate_command\n    formatted = format_output(title, cur, headers, status, settings)\n  File "/usr/local/Cellar/pgcli/3.0.0/libexec/lib/python3.8/site-packages/pgcli/main.py", line 1432, in format_output\n    first_line = next(formatted)\nStopIteration\n'
2020-10-13 16:45:46,645 (49537/MainThread) pgcli.main ERROR - sql: "select * from notify_notification_groups WHERE group_id = '176925';", error: StopIteration()
2020-10-13 16:45:46,645 (49537/MainThread) pgcli.main ERROR - traceback: 'Traceback (most recent call last):\n  File "/usr/local/Cellar/pgcli/3.0.0/libexec/lib/python3.8/site-packages/pgcli/main.py", line 634, in execute_command\n    output, query = self._evaluate_command(text)\n  File "/usr/local/Cellar/pgcli/3.0.0/libexec/lib/python3.8/site-packages/pgcli/main.py", line 909, in _evaluate_command\n    formatted = format_output(title, cur, headers, status, settings)\n  File "/usr/local/Cellar/pgcli/3.0.0/libexec/lib/python3.8/site-packages/pgcli/main.py", line 1432, in format_output\n    first_line = next(formatted)\nStopIteration\n'
2020-10-13 16:45:50,862 (49537/MainThread) pgcli.pgexecute ERROR - sql: 'select * from notify_notification_groups WHERE group_id = "176925"', error: UndefinedColumn('column "176925" does not exist\nLINE 1: ... * from notify_notification_groups WHERE group_id = "176925"\n                                                               ^\n')
2020-10-13 16:45:50,862 (49537/MainThread) pgcli.pgexecute ERROR - traceback: 'Traceback (most recent call last):\n  File "/usr/local/Cellar/pgcli/3.0.0/libexec/lib/python3.8/site-packages/pgcli/pgexecute.py", line 409, in run\n    yield self.execute_normal_sql(sql) + (sql, True, False)\n  File "/usr/local/Cellar/pgcli/3.0.0/libexec/lib/python3.8/site-packages/pgcli/pgexecute.py", line 444, in execute_normal_sql\n    cur.execute(split_sql)\npsycopg2.errors.UndefinedColumn: column "176925" does not exist\nLINE 1: ... * from notify_notification_groups WHERE group_id = "176925"\n                                                               ^\n\n'
2020-10-13 16:45:54,820 (49537/MainThread) pgcli.main ERROR - sql: "select * from notify_notification_groups WHERE group_id = '176925';", error: StopIteration()
2020-10-13 16:45:54,820 (49537/MainThread) pgcli.main ERROR - traceback: 'Traceback (most recent call last):\n  File "/usr/local/Cellar/pgcli/3.0.0/libexec/lib/python3.8/site-packages/pgcli/main.py", line 634, in execute_command\n    output, query = self._evaluate_command(text)\n  File "/usr/local/Cellar/pgcli/3.0.0/libexec/lib/python3.8/site-packages/pgcli/main.py", line 909, in _evaluate_command\n    formatted = format_output(title, cur, headers, status, settings)\n  File "/usr/local/Cellar/pgcli/3.0.0/libexec/lib/python3.8/site-packages/pgcli/main.py", line 1432, in format_output\n    first_line = next(formatted)\nStopIteration\n'
2020-10-13 16:46:04,561 (49537/MainThread) pgcli.main ERROR - sql: "select * from notify_notification_groups WHERE id = '176925';", error: StopIteration()
2020-10-13 16:46:04,561 (49537/MainThread) pgcli.main ERROR - traceback: 'Traceback (most recent call last):\n  File "/usr/local/Cellar/pgcli/3.0.0/libexec/lib/python3.8/site-packages/pgcli/main.py", line 634, in execute_command\n    output, query = self._evaluate_command(text)\n  File "/usr/local/Cellar/pgcli/3.0.0/libexec/lib/python3.8/site-packages/pgcli/main.py", line 909, in _evaluate_command\n    formatted = format_output(title, cur, headers, status, settings)\n  File "/usr/local/Cellar/pgcli/3.0.0/libexec/lib/python3.8/site-packages/pgcli/main.py", line 1432, in format_output\n    first_line = next(formatted)\nStopIteration\n'
2020-10-13 16:47:48,876 (49537/MainThread) pgcli.main ERROR - sql: "select * from notify_notification_groups where notification_id = 'c9e4abc8-ad80-40e1-94b0-fdbd60797ffa';", error: StopIteration()
2020-10-13 16:47:48,877 (49537/MainThread) pgcli.main ERROR - traceback: 'Traceback (most recent call last):\n  File "/usr/local/Cellar/pgcli/3.0.0/libexec/lib/python3.8/site-packages/pgcli/main.py", line 634, in execute_command\n    output, query = self._evaluate_command(text)\n  File "/usr/local/Cellar/pgcli/3.0.0/libexec/lib/python3.8/site-packages/pgcli/main.py", line 909, in _evaluate_command\n    formatted = format_output(title, cur, headers, status, settings)\n  File "/usr/local/Cellar/pgcli/3.0.0/libexec/lib/python3.8/site-packages/pgcli/main.py", line 1432, in format_output\n    first_line = next(formatted)\nStopIteration\n'
2020-10-13 16:48:03,432 (49537/MainThread) pgcli.pgexecute ERROR - sql: "select * from * where id = 'c9e4abc8-ad80-40e1-94b0-fdbd60797ffa'", error: SyntaxError('syntax error at or near "*"\nLINE 1: select * from * where id = \'c9e4abc8-ad80-40e1-94b0-fdbd6079...\n                      ^\n')
2020-10-13 16:48:03,433 (49537/MainThread) pgcli.pgexecute ERROR - traceback: 'Traceback (most recent call last):\n  File "/usr/local/Cellar/pgcli/3.0.0/libexec/lib/python3.8/site-packages/pgcli/pgexecute.py", line 409, in run\n    yield self.execute_normal_sql(sql) + (sql, True, False)\n  File "/usr/local/Cellar/pgcli/3.0.0/libexec/lib/python3.8/site-packages/pgcli/pgexecute.py", line 444, in execute_normal_sql\n    cur.execute(split_sql)\npsycopg2.errors.SyntaxError: syntax error at or near "*"\nLINE 1: select * from * where id = \'c9e4abc8-ad80-40e1-94b0-fdbd6079...\n                      ^\n\n'
2020-10-13 16:48:09,388 (49537/MainThread) pgcli.pgexecute ERROR - sql: "select * from  where id = 'c9e4abc8-ad80-40e1-94b0-fdbd60797ffa'", error: SyntaxError('syntax error at or near "where"\nLINE 1: select * from  where id = \'c9e4abc8-ad80-40e1-94b0-fdbd60797...\n                       ^\n')
2020-10-13 16:48:09,389 (49537/MainThread) pgcli.pgexecute ERROR - traceback: 'Traceback (most recent call last):\n  File "/usr/local/Cellar/pgcli/3.0.0/libexec/lib/python3.8/site-packages/pgcli/pgexecute.py", line 409, in run\n    yield self.execute_normal_sql(sql) + (sql, True, False)\n  File "/usr/local/Cellar/pgcli/3.0.0/libexec/lib/python3.8/site-packages/pgcli/pgexecute.py", line 444, in execute_normal_sql\n    cur.execute(split_sql)\npsycopg2.errors.SyntaxError: syntax error at or near "where"\nLINE 1: select * from  where id = \'c9e4abc8-ad80-40e1-94b0-fdbd60797...\n                       ^\n\n'
2020-10-13 16:48:40,075 (49537/MainThread) pgcli.main ERROR - sql: '\\dt information_schema', error: StopIteration()
2020-10-13 16:48:40,076 (49537/MainThread) pgcli.main ERROR - traceback: 'Traceback (most recent call last):\n  File "/usr/local/Cellar/pgcli/3.0.0/libexec/lib/python3.8/site-packages/pgcli/main.py", line 634, in execute_command\n    output, query = self._evaluate_command(text)\n  File "/usr/local/Cellar/pgcli/3.0.0/libexec/lib/python3.8/site-packages/pgcli/main.py", line 909, in _evaluate_command\n    formatted = format_output(title, cur, headers, status, settings)\n  File "/usr/local/Cellar/pgcli/3.0.0/libexec/lib/python3.8/site-packages/pgcli/main.py", line 1432, in format_output\n    first_line = next(formatted)\nStopIteration\n'
2020-10-13 16:48:57,089 (49537/MainThread) pgcli.main ERROR - sql: '\\dT auth_group_permissions', error: StopIteration()
2020-10-13 16:48:57,089 (49537/MainThread) pgcli.main ERROR - traceback: 'Traceback (most recent call last):\n  File "/usr/local/Cellar/pgcli/3.0.0/libexec/lib/python3.8/site-packages/pgcli/main.py", line 634, in execute_command\n    output, query = self._evaluate_command(text)\n  File "/usr/local/Cellar/pgcli/3.0.0/libexec/lib/python3.8/site-packages/pgcli/main.py", line 909, in _evaluate_command\n    formatted = format_output(title, cur, headers, status, settings)\n  File "/usr/local/Cellar/pgcli/3.0.0/libexec/lib/python3.8/site-packages/pgcli/main.py", line 1432, in format_output\n    first_line = next(formatted)\nStopIteration\n'
2020-10-13 16:49:16,786 (49537/MainThread) pgcli.pgexecute ERROR - sql: 'select * from auth_group_permission ORDER BY random() LIMIT 1', error: UndefinedTable('relation "auth_group_permission" does not exist\nLINE 1: select * from auth_group_permission ORDER BY random() LIMIT ...\n                      ^\n')
2020-10-13 16:49:16,786 (49537/MainThread) pgcli.pgexecute ERROR - traceback: 'Traceback (most recent call last):\n  File "/usr/local/Cellar/pgcli/3.0.0/libexec/lib/python3.8/site-packages/pgcli/pgexecute.py", line 409, in run\n    yield self.execute_normal_sql(sql) + (sql, True, False)\n  File "/usr/local/Cellar/pgcli/3.0.0/libexec/lib/python3.8/site-packages/pgcli/pgexecute.py", line 444, in execute_normal_sql\n    cur.execute(split_sql)\npsycopg2.errors.UndefinedTable: relation "auth_group_permission" does not exist\nLINE 1: select * from auth_group_permission ORDER BY random() LIMIT ...\n                      ^\n\n'
2020-10-13 16:52:46,172 (49537/MainThread) pgcli.main ERROR - sql: "select * from customer_customeradmin_allowed_groups where group_id = '59437';", error: StopIteration()
2020-10-13 16:52:46,173 (49537/MainThread) pgcli.main ERROR - traceback: 'Traceback (most recent call last):\n  File "/usr/local/Cellar/pgcli/3.0.0/libexec/lib/python3.8/site-packages/pgcli/main.py", line 634, in execute_command\n    output, query = self._evaluate_command(text)\n  File "/usr/local/Cellar/pgcli/3.0.0/libexec/lib/python3.8/site-packages/pgcli/main.py", line 909, in _evaluate_command\n    formatted = format_output(title, cur, headers, status, settings)\n  File "/usr/local/Cellar/pgcli/3.0.0/libexec/lib/python3.8/site-packages/pgcli/main.py", line 1432, in format_output\n    first_line = next(formatted)\nStopIteration\n'
2020-10-13 16:54:53,889 (49537/MainThread) pgcli.pgexecute ERROR - sql: "select * from customer_customeradmin inner joins customer_customeradmin_allowed_groups on customer_customeradmin.id = customer_customeradmin_allowed_groups.customeradmin_id where id = '59437'", error: SyntaxError('syntax error at or near "joins"\nLINE 1: select * from customer_customeradmin inner joins customer_cu...\n                                                   ^\n')
2020-10-13 16:54:53,890 (49537/MainThread) pgcli.pgexecute ERROR - traceback: 'Traceback (most recent call last):\n  File "/usr/local/Cellar/pgcli/3.0.0/libexec/lib/python3.8/site-packages/pgcli/pgexecute.py", line 409, in run\n    yield self.execute_normal_sql(sql) + (sql, True, False)\n  File "/usr/local/Cellar/pgcli/3.0.0/libexec/lib/python3.8/site-packages/pgcli/pgexecute.py", line 444, in execute_normal_sql\n    cur.execute(split_sql)\npsycopg2.errors.SyntaxError: syntax error at or near "joins"\nLINE 1: select * from customer_customeradmin inner joins customer_cu...\n                                                   ^\n\n'
2020-10-13 16:55:05,991 (49537/MainThread) pgcli.pgexecute ERROR - sql: "select * from customer_customeradmin inner join customer_customeradmin_allowed_groups on customer_customeradmin.id = customer_customeradmin_allowed_groups.customeradmin_id where id = '59437'", error: AmbiguousColumn('column reference "id" is ambiguous\nLINE 1: ...stomeradmin_allowed_groups.customeradmin_id where id = \'5943...\n                                                             ^\n')
2020-10-13 16:55:05,991 (49537/MainThread) pgcli.pgexecute ERROR - traceback: 'Traceback (most recent call last):\n  File "/usr/local/Cellar/pgcli/3.0.0/libexec/lib/python3.8/site-packages/pgcli/pgexecute.py", line 409, in run\n    yield self.execute_normal_sql(sql) + (sql, True, False)\n  File "/usr/local/Cellar/pgcli/3.0.0/libexec/lib/python3.8/site-packages/pgcli/pgexecute.py", line 444, in execute_normal_sql\n    cur.execute(split_sql)\npsycopg2.errors.AmbiguousColumn: column reference "id" is ambiguous\nLINE 1: ...stomeradmin_allowed_groups.customeradmin_id where id = \'5943...\n                                                             ^\n\n'
2020-10-13 16:55:16,838 (49537/MainThread) pgcli.main ERROR - sql: "select * from customer_customeradmin inner join customer_customeradmin_allowed_groups on customer_customeradmin.id = customer_customeradmin_allowed_groups.customeradmin_id where customer_customeradmin.id = '59437';", error: StopIteration()
2020-10-13 16:55:16,838 (49537/MainThread) pgcli.main ERROR - traceback: 'Traceback (most recent call last):\n  File "/usr/local/Cellar/pgcli/3.0.0/libexec/lib/python3.8/site-packages/pgcli/main.py", line 634, in execute_command\n    output, query = self._evaluate_command(text)\n  File "/usr/local/Cellar/pgcli/3.0.0/libexec/lib/python3.8/site-packages/pgcli/main.py", line 909, in _evaluate_command\n    formatted = format_output(title, cur, headers, status, settings)\n  File "/usr/local/Cellar/pgcli/3.0.0/libexec/lib/python3.8/site-packages/pgcli/main.py", line 1432, in format_output\n    first_line = next(formatted)\nStopIteration\n'
